Workbook

Sheet Total Price List (v2)
M1: =Dimension!B2 -> 0 | N1: =Dimension!C2 -> 0 | O1: =Dimension!D2 -> 0 | P1: =Dimension!E2 -> 0 | Q1: =Dimension!F2 -> 0 | R1: =Dimension!G2 -> 0 | S1: =Dimension!H2 -> 0 | T1: =Dimension!I2 -> 0 | ... FB1: =Dimension!EQ2 -> 0
M2: =Dimension!B3 -> 0 | N2: =Dimension!C3 -> 0 | O2: =Dimension!D3 -> 0 | P2: =Dimension!E3 -> 0 | Q2: =Dimension!F3 -> 0 | R2: =Dimension!G3 -> 0 | S2: =Dimension!H3 -> 0 | T2: =Dimension!I3 -> 0 | ... FB2: =Dimension!EQ3 -> 0
M3: =Dimension!B4 -> 0 | N3: =Dimension!C4 -> 0 | O3: =Dimension!D4 -> 0 | P3: =Dimension!E4 -> 0 | Q3: =Dimension!F4 -> 0 | R3: =Dimension!G4 -> 0 | S3: =Dimension!H4 -> 0 | T3: =Dimension!I4 -> 0 | ... FB3: =Dimension!EQ4 -> 0
M4: =Dimension!B5 -> 0 | N4: =Dimension!C5 -> 0 | O4: =Dimension!D5 -> 0 | P4: =Dimension!E5 -> 0 | Q4: =Dimension!F5 -> 0 | R4: =Dimension!G5 -> 0 | S4: =Dimension!H5 -> 0 | T4: =Dimension!I5 -> 0 | ... FB4: =Dimension!EQ5 -> 0
A5: Name | B5: Index | C5: ID | D5: Product Code | E5: Location Code | F5: Internal Reference | G5: eCommerce Description | H5: Price computation | I5: Cost | J5: Associated Service | K5: Associated Work Center | L5: Associated Cost per Employee per Hour | M5: Margin | N5: =Dimension!C6 -> 0 | O5: =Dimension!D6 -> 0 | P5: =Dimension!E6 -> 0 | Q5: =Dimension!F6 -> 0 | R5: =Dimension!G6 -> 0 | S5: =Dimension!H6 -> 0 | T5: =Dimension!I6 -> 0 | U5: =Dimension!J6 -> 0 | ... FB5: =Dimension!EQ6 -> 0
A6: "COLORBOX" BAKLIJST GROEN DONKERGRIJS 40X33 | B6: 1 | C6: 9896 | D6: 76130 | E6: .C04+C25 | G6: <div data-oe-version="2.0">Test description</div> | H6: Circumference | I6: 3.06 | J6: Lijst snijden | K6: Lijst snijden | L6: 40 | M6: =('Pricelists by Sequence'!$D$2*(-1)/100) -> 0 | N6: {=(IF($H6=$M$4,N$4*$I6,N$3*$I6)+(INDEX(_xlfn._xlws.FILTER('Service Duration by unit'!$D$1:$D$400,('Service Duration by unit'!$A$1:$A$400=$J6)*('Service Duration by unit'!$C$1:$C$400=_xlfn.MINIFS('Service Duration by unit'!$C$1:$C$400,'Service Duration by unit'!$A$1:$A$400,$J6,'Service Duration by unit'!$C$1:$C$400,">="&IF($H6=$M$4,N$4,N$3)))),1))*$L6/3600)*(1+$M6)} -> 0 | O6: {=(IF($H6=$M$4,N$4*$I6,N$3*$I6)+(INDEX(_xlfn._xlws.FILTER('Service Duration by unit'!$D$1:$D$400,('Service Duration by unit'!$A$1:$A$400=$J6)*('Service Duration by unit'!$C$1:$C$400=_xlfn.MINIFS('Service Duration by unit'!$C$1:$C$400,'Service Duration by unit'!$A$1:$A$400,$J6,'Service Duration by unit'!$C$1:$C$400,">="&IF($H6=$M$4,N$4,N$3)))),1))*$L6/3600)*(1+$M6)} -> 0 | P6: {=(IF($H6=$M$4,N$4*$I6,N$3*$I6)+(INDEX(_xlfn._xlws.FILTER('Service Duration by unit'!$D$1:$D$400,('Service Duration by unit'!$A$1:$A$400=$J6)*('Service Duration by unit'!$C$1:$C$400=_xlfn.MINIFS('Service Duration by unit'!$C$1:$C$400,'Service Duration by unit'!$A$1:$A$400,$J6,'Service Duration by unit'!$C$1:$C$400,">="&IF($H6=$M$4,N$4,N$3)))),1))*$L6/3600)*(1+$M6)} -> 0 | Q6: {=(IF($H6=$M$4,N$4*$I6,N$3*$I6)+(INDEX(_xlfn._xlws.FILTER('Service Duration by unit'!$D$1:$D$400,('Service Duration by unit'!$A$1:$A$400=$J6)*('Service Duration by unit'!$C$1:$C$400=_xlfn.MINIFS('Service Duration by unit'!$C$1:$C$400,'Service Duration by unit'!$A$1:$A$400,$J6,'Service Duration by unit'!$C$1:$C$400,">="&IF($H6=$M$4,N$4,N$3)))),1))*$L6/3600)*(1+$M6)} -> 0 | R6: {=(IF($H6=$M$4,N$4*$I6,N$3*$I6)+(INDEX(_xlfn._xlws.FILTER('Service Duration by unit'!$D$1:$D$400,('Service Duration by unit'!$A$1:$A$400=$J6)*('Service Duration by unit'!$C$1:$C$400=_xlfn.MINIFS('Service Duration by unit'!$C$1:$C$400,'Service Duration by unit'!$A$1:$A$400,$J6,'Service Duration by unit'!$C$1:$C$400,">="&IF($H6=$M$4,N$4,N$3)))),1))*$L6/3600)*(1+$M6)} -> 0 | S6: {=(IF($H6=$M$4,N$4*$I6,N$3*$I6)+(INDEX(_xlfn._xlws.FILTER('Service Duration by unit'!$D$1:$D$400,('Service Duration by unit'!$A$1:$A$400=$J6)*('Service Duration by unit'!$C$1:$C$400=_xlfn.MINIFS('Service Duration by unit'!$C$1:$C$400,'Service Duration by unit'!$A$1:$A$400,$J6,'Service Duration by unit'!$C$1:$C$400,">="&IF($H6=$M$4,N$4,N$3)))),1))*$L6/3600)*(1+$M6)} -> 0 | T6: {=(IF($H6=$M$4,N$4*$I6,N$3*$I6)+(INDEX(_xlfn._xlws.FILTER('Service Duration by unit'!$D$1:$D$400,('Service Duration by unit'!$A$1:$A$400=$J6)*('Service Duration by unit'!$C$1:$C$400=_xlfn.MINIFS('Service Duration by unit'!$C$1:$C$400,'Service Duration by unit'!$A$1:$A$400,$J6,'Service Duration by unit'!$C$1:$C$400,">="&IF($H6=$M$4,N$4,N$3)))),1))*$L6/3600)*(1+$M6)} -> 0 | U6: {=(IF($H6=$M$4,N$4*$I6,N$3*$I6)+(INDEX(_xlfn._xlws.FILTER('Service Duration by unit'!$D$1:$D$400,('Service Duration by unit'!$A$1:$A$400=$J6)*('Service Duration by unit'!$C$1:$C$400=_xlfn.MINIFS('Service Duration by unit'!$C$1:$C$400,'Service Duration by unit'!$A$1:$A$400,$J6,'Service Duration by unit'!$C$1:$C$400,">="&IF($H6=$M$4,N$4,N$3)))),1))*$L6/3600)*(1+$M6)} -> 0 | V6: {=(IF($H6=$M$4,N$4*$I6,N$3*$I6)+(INDEX(_xlfn._xlws.FILTER('Service Duration by unit'!$D$1:$D$400,('Service Duration by unit'!$A$1:$A$400=$J6)*('Service Duration by unit'!$C$1:$C$400=_xlfn.MINIFS('Service Duration by unit'!$C$1:$C$400,'Service Duration by unit'!$A$1:$A$400,$J6,'Service Duration by unit'!$C$1:$C$400,">="&IF($H6=$M$4,N$4,N$3)))),1))*$L6/3600)*(1+$M6)} -> 0 | W6: {=(IF($H6=$M$4,N$4*$I6,N$3*$I6)+(INDEX(_xlfn._xlws.FILTER('Service Duration by unit'!$D$1:$D$400,('Service Duration by unit'!$A$1:$A$400=$J6)*('Service Duration by unit'!$C$1:$C$400=_xlfn.MINIFS('Service Duration by unit'!$C$1:$C$400,'Service Duration by unit'!$A$1:$A$400,$J6,'Service Duration by unit'!$C$1:$C$400,">="&IF($H6=$M$4,N$4,N$3)))),1))*$L6/3600)*(1+$M6)} -> 0 | X6: {=(IF($H6=$M$4,N$4*$I6,N$3*$I6)+(INDEX(_xlfn._xlws.FILTER('Service Duration by unit'!$D$1:$D$400,('Service Duration by unit'!$A$1:$A$400=$J6)*('Service Duration by unit'!$C$1:$C$400=_xlfn.MINIFS('Service Duration by unit'!$C$1:$C$400,'Service Duration by unit'!$A$1:$A$400,$J6,'Service Duration by unit'!$C$1:$C$400,">="&IF($H6=$M$4,N$4,N$3)))),1))*$L6/3600)*(1+$M6)} -> 0 | Y6: {=(IF($H6=$M$4,N$4*$I6,N$3*$I6)+(INDEX(_xlfn._xlws.FILTER('Service Duration by unit'!$D$1:$D$400,('Service Duration by unit'!$A$1:$A$400=$J6)*('Service Duration by unit'!$C$1:$C$400=_xlfn.MINIFS('Service Duration by unit'!$C$1:$C$400,'Service Duration by unit'!$A$1:$A$400,$J6,'Service Duration by unit'!$C$1:$C$400,">="&IF($H6=$M$4,N$4,N$3)))),1))*$L6/3600)*(1+$M6)} -> 0 | Z6: {=(IF($H6=$M$4,N$4*$I6,N$3*$I6)+(INDEX(_xlfn._xlws.FILTER('Service Duration by unit'!$D$1:$D$400,('Service Duration by unit'!$A$1:$A$400=$J6)*('Service Duration by unit'!$C$1:$C$400=_xlfn.MINIFS('Service Duration by unit'!$C$1:$C$400,'Service Duration by unit'!$A$1:$A$400,$J6,'Service Duration by unit'!$C$1:$C$400,">="&IF($H6=$M$4,N$4,N$3)))),1))*$L6/3600)*(1+$M6)} -> 0 | AA6: {=(IF($H6=$M$4,N$4*$I6,N$3*$I6)+(INDEX(_xlfn._xlws.FILTER('Service Duration by unit'!$D$1:$D$400,('Service Duration by unit'!$A$1:$A$400=$J6)*('Service Duration by unit'!$C$1:$C$400=_xlfn.MINIFS('Service Duration by unit'!$C$1:$C$400,'Service Duration by unit'!$A$1:$A$400,$J6,'Service Duration by unit'!$C$1:$C$400,">="&IF($H6=$M$4,N$4,N$3)))),1))*$L6/3600)*(1+$M6)} -> 0 | AB6: {=(IF($H6=$M$4,N$4*$I6,N$3*$I6)+(INDEX(_xlfn._xlws.FILTER('Service Duration by unit'!$D$1:$D$400,('Service Duration by unit'!$A$1:$A$400=$J6)*('Service Duration by unit'!$C$1:$C$400=_xlfn.MINIFS('Service Duration by unit'!$C$1:$C$400,'Service Duration by unit'!$A$1:$A$400,$J6,'Service Duration by unit'!$C$1:$C$400,">="&IF($H6=$M$4,N$4,N$3)))),1))*$L6/3600)*(1+$M6)} -> 0 | AC6: {=(IF($H6=$M$4,N$4*$I6,N$3*$I6)+(INDEX(_xlfn._xlws.FILTER('Service Duration by unit'!$D$1:$D$400,('Service Duration by unit'!$A$1:$A$400=$J6)*('Service Duration by unit'!$C$1:$C$400=_xlfn.MINIFS('Service Duration by unit'!$C$1:$C$400,'Service Duration by unit'!$A$1:$A$400,$J6,'Service Duration by unit'!$C$1:$C$400,">="&IF($H6=$M$4,N$4,N$3)))),1))*$L6/3600)*(1+$M6)} -> 0 | AD6: {=(IF($H6=$M$4,N$4*$I6,N$3*$I6)+(INDEX(_xlfn._xlws.FILTER('Service Duration by unit'!$D$1:$D$400,('Service Duration by unit'!$A$1:$A$400=$J6)*('Service Duration by unit'!$C$1:$C$400=_xlfn.MINIFS('Service Duration by unit'!$C$1:$C$400,'Service Duration by unit'!$A$1:$A$400,$J6,'Service Duration by unit'!$C$1:$C$400,">="&IF($H6=$M$4,N$4,N$3)))),1))*$L6/3600)*(1+$M6)} -> 0 | AE6: {=(IF($H6=$M$4,N$4*$I6,N$3*$I6)+(INDEX(_xlfn._xlws.FILTER('Service Duration by unit'!$D$1:$D$400,('Service Duration by unit'!$A$1:$A$400=$J6)*('Service Duration by unit'!$C$1:$C$400=_xlfn.MINIFS('Service Duration by unit'!$C$1:$C$400,'Service Duration by unit'!$A$1:$A$400,$J6,'Service Duration by unit'!$C$1:$C$400,">="&IF($H6=$M$4,N$4,N$3)))),1))*$L6/3600)*(1+$M6)} -> 0 | AF6: {=(IF($H6=$M$4,N$4*$I6,N$3*$I6)+(INDEX(_xlfn._xlws.FILTER('Service Duration by unit'!$D$1:$D$400,('Service Duration by unit'!$A$1:$A$400=$J6)*('Service Duration by unit'!$C$1:$C$400=_xlfn.MINIFS('Service Duration by unit'!$C$1:$C$400,'Service Duration by unit'!$A$1:$A$400,$J6,'Service Duration by unit'!$C$1:$C$400,">="&IF($H6=$M$4,N$4,N$3)))),1))*$L6/3600)*(1+$M6)} -> 0 | AG6: {=(IF($H6=$M$4,N$4*$I6,N$3*$I6)+(INDEX(_xlfn._xlws.FILTER('Service Duration by unit'!$D$1:$D$400,('Service Duration by unit'!$A$1:$A$400=$J6)*('Service Duration by unit'!$C$1:$C$400=_xlfn.MINIFS('Service Duration by unit'!$C$1:$C$400,'Service Duration by unit'!$A$1:$A$400,$J6,'Service Duration by unit'!$C$1:$C$400,">="&IF($H6=$M$4,N$4,N$3)))),1))*$L6/3600)*(1+$M6)} -> 0 | AH6: {=(IF($H6=$M$4,N$4*$I6,N$3*$I6)+(INDEX(_xlfn._xlws.FILTER('Service Duration by unit'!$D$1:$D$400,('Service Duration by unit'!$A$1:$A$400=$J6)*('Service Duration by unit'!$C$1:$C$400=_xlfn.MINIFS('Service Duration by unit'!$C$1:$C$400,'Service Duration by unit'!$A$1:$A$400,$J6,'Service Duration by unit'!$C$1:$C$400,">="&IF($H6=$M$4,N$4,N$3)))),1))*$L6/3600)*(1+$M6)} -> 0 | AI6: {=(IF($H6=$M$4,N$4*$I6,N$3*$I6)+(INDEX(_xlfn._xlws.FILTER('Service Duration by unit'!$D$1:$D$400,('Service Duration by unit'!$A$1:$A$400=$J6)*('Service Duration by unit'!$C$1:$C$400=_xlfn.MINIFS('Service Duration by unit'!$C$1:$C$400,'Service Duration by unit'!$A$1:$A$400,$J6,'Service Duration by unit'!$C$1:$C$400,">="&IF($H6=$M$4,N$4,N$3)))),1))*$L6/3600)*(1+$M6)} -> 0 | AJ6: {=(IF($H6=$M$4,N$4*$I6,N$3*$I6)+(INDEX(_xlfn._xlws.FILTER('Service Duration by unit'!$D$1:$D$400,('Service Duration by unit'!$A$1:$A$400=$J6)*('Service Duration by unit'!$C$1:$C$400=_xlfn.MINIFS('Service Duration by unit'!$C$1:$C$400,'Service Duration by unit'!$A$1:$A$400,$J6,'Service Duration by unit'!$C$1:$C$400,">="&IF($H6=$M$4,N$4,N$3)))),1))*$L6/3600)*(1+$M6)} -> 0 | AK6: {=(IF($H6=$M$4,N$4*$I6,N$3*$I6)+(INDEX(_xlfn._xlws.FILTER('Service Duration by unit'!$D$1:$D$400,('Service Duration by unit'!$A$1:$A$400=$J6)*('Service Duration by unit'!$C$1:$C$400=_xlfn.MINIFS('Service Duration by unit'!$C$1:$C$400,'Service Duration by unit'!$A$1:$A$400,$J6,'Service Duration by unit'!$C$1:$C$400,">="&IF($H6=$M$4,N$4,N$3)))),1))*$L6/3600)*(1+$M6)} -> 0 | AL6: {=(IF($H6=$M$4,N$4*$I6,N$3*$I6)+(INDEX(_xlfn._xlws.FILTER('Service Duration by unit'!$D$1:$D$400,('Service Duration by unit'!$A$1:$A$400=$J6)*('Service Duration by unit'!$C$1:$C$400=_xlfn.MINIFS('Service Duration by unit'!$C$1:$C$400,'Service Duration by unit'!$A$1:$A$400,$J6,'Service Duration by unit'!$C$1:$C$400,">="&IF($H6=$M$4,N$4,N$3)))),1))*$L6/3600)*(1+$M6)} -> 0 | AM6: {=(IF($H6=$M$4,N$4*$I6,N$3*$I6)+(INDEX(_xlfn._xlws.FILTER('Service Duration by unit'!$D$1:$D$400,('Service Duration by unit'!$A$1:$A$400=$J6)*('Service Duration by unit'!$C$1:$C$400=_xlfn.MINIFS('Service Duration by unit'!$C$1:$C$400,'Service Duration by unit'!$A$1:$A$400,$J6,'Service Duration by unit'!$C$1:$C$400,">="&IF($H6=$M$4,N$4,N$3)))),1))*$L6/3600)*(1+$M6)} -> 0 | AN6: {=(IF($H6=$M$4,N$4*$I6,N$3*$I6)+(INDEX(_xlfn._xlws.FILTER('Service Duration by unit'!$D$1:$D$400,('Service Duration by unit'!$A$1:$A$400=$J6)*('Service Duration by unit'!$C$1:$C$400=_xlfn.MINIFS('Service Duration by unit'!$C$1:$C$400,'Service Duration by unit'!$A$1:$A$400,$J6,'Service Duration by unit'!$C$1:$C$400,">="&IF($H6=$M$4,N$4,N$3)))),1))*$L6/3600)*(1+$M6)} -> 0 | AO6: {=(IF($H6=$M$4,N$4*$I6,N$3*$I6)+(INDEX(_xlfn._xlws.FILTER('Service Duration by unit'!$D$1:$D$400,('Service Duration by unit'!$A$1:$A$400=$J6)*('Service Duration by unit'!$C$1:$C$400=_xlfn.MINIFS('Service Duration by unit'!$C$1:$C$400,'Service Duration by unit'!$A$1:$A$400,$J6,'Service Duration by unit'!$C$1:$C$400,">="&IF($H6=$M$4,N$4,N$3)))),1))*$L6/3600)*(1+$M6)} -> 0 | AP6: {=(IF($H6=$M$4,N$4*$I6,N$3*$I6)+(INDEX(_xlfn._xlws.FILTER('Service Duration by unit'!$D$1:$D$400,('Service Duration by unit'!$A$1:$A$400=$J6)*('Service Duration by unit'!$C$1:$C$400=_xlfn.MINIFS('Service Duration by unit'!$C$1:$C$400,'Service Duration by unit'!$A$1:$A$400,$J6,'Service Duration by unit'!$C$1:$C$400,">="&IF($H6=$M$4,N$4,N$3)))),1))*$L6/3600)*(1+$M6)} -> 0 | AQ6: {=(IF($H6=$M$4,N$4*$I6,N$3*$I6)+(INDEX(_xlfn._xlws.FILTER('Service Duration by unit'!$D$1:$D$400,('Service Duration by unit'!$A$1:$A$400=$J6)*('Service Duration by unit'!$C$1:$C$400=_xlfn.MINIFS('Service Duration by unit'!$C$1:$C$400,'Service Duration by unit'!$A$1:$A$400,$J6,'Service Duration by unit'!$C$1:$C$400,">="&IF($H6=$M$4,N$4,N$3)))),1))*$L6/3600)*(1+$M6)} -> 0 | AR6: {=(IF($H6=$M$4,N$4*$I6,N$3*$I6)+(INDEX(_xlfn._xlws.FILTER('Service Duration by unit'!$D$1:$D$400,('Service Duration by unit'!$A$1:$A$400=$J6)*('Service Duration by unit'!$C$1:$C$400=_xlfn.MINIFS('Service Duration by unit'!$C$1:$C$400,'Service Duration by unit'!$A$1:$A$400,$J6,'Service Duration by unit'!$C$1:$C$400,">="&IF($H6=$M$4,N$4,N$3)))),1))*$L6/3600)*(1+$M6)} -> 0 | AS6: {=(IF($H6=$M$4,N$4*$I6,N$3*$I6)+(INDEX(_xlfn._xlws.FILTER('Service Duration by unit'!$D$1:$D$400,('Service Duration by unit'!$A$1:$A$400=$J6)*('Service Duration by unit'!$C$1:$C$400=_xlfn.MINIFS('Service Duration by unit'!$C$1:$C$400,'Service Duration by unit'!$A$1:$A$400,$J6,'Service Duration by unit'!$C$1:$C$400,">="&IF($H6=$M$4,N$4,N$3)))),1))*$L6/3600)*(1+$M6)} -> 0 | AT6: {=(IF($H6=$M$4,N$4*$I6,N$3*$I6)+(INDEX(_xlfn._xlws.FILTER('Service Duration by unit'!$D$1:$D$400,('Service Duration by unit'!$A$1:$A$400=$J6)*('Service Duration by unit'!$C$1:$C$400=_xlfn.MINIFS('Service Duration by unit'!$C$1:$C$400,'Service Duration by unit'!$A$1:$A$400,$J6,'Service Duration by unit'!$C$1:$C$400,">="&IF($H6=$M$4,N$4,N$3)))),1))*$L6/3600)*(1+$M6)} -> 0 | AU6: {=(IF($H6=$M$4,N$4*$I6,N$3*$I6)+(INDEX(_xlfn._xlws.FILTER('Service Duration by unit'!$D$1:$D$400,('Service Duration by unit'!$A$1:$A$400=$J6)*('Service Duration by unit'!$C$1:$C$400=_xlfn.MINIFS('Service Duration by unit'!$C$1:$C$400,'Service Duration by unit'!$A$1:$A$400,$J6,'Service Duration by unit'!$C$1:$C$400,">="&IF($H6=$M$4,N$4,N$3)))),1))*$L6/3600)*(1+$M6)} -> 0 | AV6: {=(IF($H6=$M$4,N$4*$I6,N$3*$I6)+(INDEX(_xlfn._xlws.FILTER('Service Duration by unit'!$D$1:$D$400,('Service Duration by unit'!$A$1:$A$400=$J6)*('Service Duration by unit'!$C$1:$C$400=_xlfn.MINIFS('Service Duration by unit'!$C$1:$C$400,'Service Duration by unit'!$A$1:$A$400,$J6,'Service Duration by unit'!$C$1:$C$400,">="&IF($H6=$M$4,N$4,N$3)))),1))*$L6/3600)*(1+$M6)} -> 0 | AW6: {=(IF($H6=$M$4,N$4*$I6,N$3*$I6)+(INDEX(_xlfn._xlws.FILTER('Service Duration by unit'!$D$1:$D$400,('Service Duration by unit'!$A$1:$A$400=$J6)*('Service Duration by unit'!$C$1:$C$400=_xlfn.MINIFS('Service Duration by unit'!$C$1:$C$400,'Service Duration by unit'!$A$1:$A$400,$J6,'Service Duration by unit'!$C$1:$C$400,">="&IF($H6=$M$4,N$4,N$3)))),1))*$L6/3600)*(1+$M6)} -> 0 | AX6: {=(IF($H6=$M$4,N$4*$I6,N$3*$I6)+(INDEX(_xlfn._xlws.FILTER('Service Duration by unit'!$D$1:$D$400,('Service Duration by unit'!$A$1:$A$400=$J6)*('Service Duration by unit'!$C$1:$C$400=_xlfn.MINIFS('Service Duration by unit'!$C$1:$C$400,'Service Duration by unit'!$A$1:$A$400,$J6,'Service Duration by unit'!$C$1:$C$400,">="&IF($H6=$M$4,N$4,N$3)))),1))*$L6/3600)*(1+$M6)} -> 0 | AY6: {=(IF($H6=$M$4,N$4*$I6,N$3*$I6)+(INDEX(_xlfn._xlws.FILTER('Service Duration by unit'!$D$1:$D$400,('Service Duration by unit'!$A$1:$A$400=$J6)*('Service Duration by unit'!$C$1:$C$400=_xlfn.MINIFS('Service Duration by unit'!$C$1:$C$400,'Service Duration by unit'!$A$1:$A$400,$J6,'Service Duration by unit'!$C$1:$C$400,">="&IF($H6=$M$4,N$4,N$3)))),1))*$L6/3600)*(1+$M6)} -> 0 | AZ6: {=(IF($H6=$M$4,N$4*$I6,N$3*$I6)+(INDEX(_xlfn._xlws.FILTER('Service Duration by unit'!$D$1:$D$400,('Service Duration by unit'!$A$1:$A$400=$J6)*('Service Duration by unit'!$C$1:$C$400=_xlfn.MINIFS('Service Duration by unit'!$C$1:$C$400,'Service Duration by unit'!$A$1:$A$400,$J6,'Service Duration by unit'!$C$1:$C$400,">="&IF($H6=$M$4,N$4,N$3)))),1))*$L6/3600)*(1+$M6)} -> 0 | BA6: {=(IF($H6=$M$4,N$4*$I6,N$3*$I6)+(INDEX(_xlfn._xlws.FILTER('Service Duration by unit'!$D$1:$D$400,('Service Duration by unit'!$A$1:$A$400=$J6)*('Service Duration by unit'!$C$1:$C$400=_xlfn.MINIFS('Service Duration by unit'!$C$1:$C$400,'Service Duration by unit'!$A$1:$A$400,$J6,'Service Duration by unit'!$C$1:$C$400,">="&IF($H6=$M$4,N$4,N$3)))),1))*$L6/3600)*(1+$M6)} -> 0 | BB6: {=(IF($H6=$M$4,N$4*$I6,N$3*$I6)+(INDEX(_xlfn._xlws.FILTER('Service Duration by unit'!$D$1:$D$400,('Service Duration by unit'!$A$1:$A$400=$J6)*('Service Duration by unit'!$C$1:$C$400=_xlfn.MINIFS('Service Duration by unit'!$C$1:$C$400,'Service Duration by unit'!$A$1:$A$400,$J6,'Service Duration by unit'!$C$1:$C$400,">="&IF($H6=$M$4,N$4,N$3)))),1))*$L6/3600)*(1+$M6)} -> 0 | BC6: {=(IF($H6=$M$4,N$4*$I6,N$3*$I6)+(INDEX(_xlfn._xlws.FILTER('Service Duration by unit'!$D$1:$D$400,('Service Duration by unit'!$A$1:$A$400=$J6)*('Service Duration by unit'!$C$1:$C$400=_xlfn.MINIFS('Service Duration by unit'!$C$1:$C$400,'Service Duration by unit'!$A$1:$A$400,$J6,'Service Duration by unit'!$C$1:$C$400,">="&IF($H6=$M$4,N$4,N$3)))),1))*$L6/3600)*(1+$M6)} -> 0 | BD6: {=(IF($H6=$M$4,N$4*$I6,N$3*$I6)+(INDEX(_xlfn._xlws.FILTER('Service Duration by unit'!$D$1:$D$400,('Service Duration by unit'!$A$1:$A$400=$J6)*('Service Duration by unit'!$C$1:$C$400=_xlfn.MINIFS('Service Duration by unit'!$C$1:$C$400,'Service Duration by unit'!$A$1:$A$400,$J6,'Service Duration by unit'!$C$1:$C$400,">="&IF($H6=$M$4,N$4,N$3)))),1))*$L6/3600)*(1+$M6)} -> 0 | BE6: {=(IF($H6=$M$4,N$4*$I6,N$3*$I6)+(INDEX(_xlfn._xlws.FILTER('Service Duration by unit'!$D$1:$D$400,('Service Duration by unit'!$A$1:$A$400=$J6)*('Service Duration by unit'!$C$1:$C$400=_xlfn.MINIFS('Service Duration by unit'!$C$1:$C$400,'Service Duration by unit'!$A$1:$A$400,$J6,'Service Duration by unit'!$C$1:$C$400,">="&IF($H6=$M$4,N$4,N$3)))),1))*$L6/3600)*(1+$M6)} -> 0 | BF6: {=(IF($H6=$M$4,N$4*$I6,N$3*$I6)+(INDEX(_xlfn._xlws.FILTER('Service Duration by unit'!$D$1:$D$400,('Service Duration by unit'!$A$1:$A$400=$J6)*('Service Duration by unit'!$C$1:$C$400=_xlfn.MINIFS('Service Duration by unit'!$C$1:$C$400,'Service Duration by unit'!$A$1:$A$400,$J6,'Service Duration by unit'!$C$1:$C$400,">="&IF($H6=$M$4,N$4,N$3)))),1))*$L6/3600)*(1+$M6)} -> 0 | BG6: {=(IF($H6=$M$4,N$4*$I6,N$3*$I6)+(INDEX(_xlfn._xlws.FILTER('Service Duration by unit'!$D$1:$D$400,('Service Duration by unit'!$A$1:$A$400=$J6)*('Service Duration by unit'!$C$1:$C$400=_xlfn.MINIFS('Service Duration by unit'!$C$1:$C$400,'Service Duration by unit'!$A$1:$A$400,$J6,'Service Duration by unit'!$C$1:$C$400,">="&IF($H6=$M$4,N$4,N$3)))),1))*$L6/3600)*(1+$M6)} -> 0 | BH6: {=(IF($H6=$M$4,N$4*$I6,N$3*$I6)+(INDEX(_xlfn._xlws.FILTER('Service Duration by unit'!$D$1:$D$400,('Service Duration by unit'!$A$1:$A$400=$J6)*('Service Duration by unit'!$C$1:$C$400=_xlfn.MINIFS('Service Duration by unit'!$C$1:$C$400,'Service Duration by unit'!$A$1:$A$400,$J6,'Service Duration by unit'!$C$1:$C$400,">="&IF($H6=$M$4,N$4,N$3)))),1))*$L6/3600)*(1+$M6)} -> 0 | BI6: {=(IF($H6=$M$4,N$4*$I6,N$3*$I6)+(INDEX(_xlfn._xlws.FILTER('Service Duration by unit'!$D$1:$D$400,('Service Duration by unit'!$A$1:$A$400=$J6)*('Service Duration by unit'!$C$1:$C$400=_xlfn.MINIFS('Service Duration by unit'!$C$1:$C$400,'Service Duration by unit'!$A$1:$A$400,$J6,'Service Duration by unit'!$C$1:$C$400,">="&IF($H6=$M$4,N$4,N$3)))),1))*$L6/3600)*(1+$M6)} -> 0 | BJ6: {=(IF($H6=$M$4,N$4*$I6,N$3*$I6)+(INDEX(_xlfn._xlws.FILTER('Service Duration by unit'!$D$1:$D$400,('Service Duration by unit'!$A$1:$A$400=$J6)*('Service Duration by unit'!$C$1:$C$400=_xlfn.MINIFS('Service Duration by unit'!$C$1:$C$400,'Service Duration by unit'!$A$1:$A$400,$J6,'Service Duration by unit'!$C$1:$C$400,">="&IF($H6=$M$4,N$4,N$3)))),1))*$L6/3600)*(1+$M6)} -> 0 | BK6: {=(IF($H6=$M$4,N$4*$I6,N$3*$I6)+(INDEX(_xlfn._xlws.FILTER('Service Duration by unit'!$D$1:$D$400,('Service Duration by unit'!$A$1:$A$400=$J6)*('Service Duration by unit'!$C$1:$C$400=_xlfn.MINIFS('Service Duration by unit'!$C$1:$C$400,'Service Duration by unit'!$A$1:$A$400,$J6,'Service Duration by unit'!$C$1:$C$400,">="&IF($H6=$M$4,N$4,N$3)))),1))*$L6/3600)*(1+$M6)} -> 0 | BL6: {=(IF($H6=$M$4,N$4*$I6,N$3*$I6)+(INDEX(_xlfn._xlws.FILTER('Service Duration by unit'!$D$1:$D$400,('Service Duration by unit'!$A$1:$A$400=$J6)*('Service Duration by unit'!$C$1:$C$400=_xlfn.MINIFS('Service Duration by unit'!$C$1:$C$400,'Service Duration by unit'!$A$1:$A$400,$J6,'Service Duration by unit'!$C$1:$C$400,">="&IF($H6=$M$4,N$4,N$3)))),1))*$L6/3600)*(1+$M6)} -> 0 | BM6: {=(IF($H6=$M$4,N$4*$I6,N$3*$I6)+(INDEX(_xlfn._xlws.FILTER('Service Duration by unit'!$D$1:$D$400,('Service Duration by unit'!$A$1:$A$400=$J6)*('Service Duration by unit'!$C$1:$C$400=_xlfn.MINIFS('Service Duration by unit'!$C$1:$C$400,'Service Duration by unit'!$A$1:$A$400,$J6,'Service Duration by unit'!$C$1:$C$400,">="&IF($H6=$M$4,N$4,N$3)))),1))*$L6/3600)*(1+$M6)} -> 0 | BN6: {=(IF($H6=$M$4,N$4*$I6,N$3*$I6)+(INDEX(_xlfn._xlws.FILTER('Service Duration by unit'!$D$1:$D$400,('Service Duration by unit'!$A$1:$A$400=$J6)*('Service Duration by unit'!$C$1:$C$400=_xlfn.MINIFS('Service Duration by unit'!$C$1:$C$400,'Service Duration by unit'!$A$1:$A$400,$J6,'Service Duration by unit'!$C$1:$C$400,">="&IF($H6=$M$4,N$4,N$3)))),1))*$L6/3600)*(1+$M6)} -> 0 | BO6: {=(IF($H6=$M$4,N$4*$I6,N$3*$I6)+(INDEX(_xlfn._xlws.FILTER('Service Duration by unit'!$D$1:$D$400,('Service Duration by unit'!$A$1:$A$400=$J6)*('Service Duration by unit'!$C$1:$C$400=_xlfn.MINIFS('Service Duration by unit'!$C$1:$C$400,'Service Duration by unit'!$A$1:$A$400,$J6,'Service Duration by unit'!$C$1:$C$400,">="&IF($H6=$M$4,N$4,N$3)))),1))*$L6/3600)*(1+$M6)} -> 0 | BP6: {=(IF($H6=$M$4,N$4*$I6,N$3*$I6)+(INDEX(_xlfn._xlws.FILTER('Service Duration by unit'!$D$1:$D$400,('Service Duration by unit'!$A$1:$A$400=$J6)*('Service Duration by unit'!$C$1:$C$400=_xlfn.MINIFS('Service Duration by unit'!$C$1:$C$400,'Service Duration by unit'!$A$1:$A$400,$J6,'Service Duration by unit'!$C$1:$C$400,">="&IF($H6=$M$4,N$4,N$3)))),1))*$L6/3600)*(1+$M6)} -> 0 | BQ6: {=(IF($H6=$M$4,N$4*$I6,N$3*$I6)+(INDEX(_xlfn._xlws.FILTER('Service Duration by unit'!$D$1:$D$400,('Service Duration by unit'!$A$1:$A$400=$J6)*('Service Duration by unit'!$C$1:$C$400=_xlfn.MINIFS('Service Duration by unit'!$C$1:$C$400,'Service Duration by unit'!$A$1:$A$400,$J6,'Service Duration by unit'!$C$1:$C$400,">="&IF($H6=$M$4,N$4,N$3)))),1))*$L6/3600)*(1+$M6)} -> 0 | BR6: {=(IF($H6=$M$4,N$4*$I6,N$3*$I6)+(INDEX(_xlfn._xlws.FILTER('Service Duration by unit'!$D$1:$D$400,('Service Duration by unit'!$A$1:$A$400=$J6)*('Service Duration by unit'!$C$1:$C$400=_xlfn.MINIFS('Service Duration by unit'!$C$1:$C$400,'Service Duration by unit'!$A$1:$A$400,$J6,'Service Duration by unit'!$C$1:$C$400,">="&IF($H6=$M$4,N$4,N$3)))),1))*$L6/3600)*(1+$M6)} -> 0 | BS6: {=(IF($H6=$M$4,N$4*$I6,N$3*$I6)+(INDEX(_xlfn._xlws.FILTER('Service Duration by unit'!$D$1:$D$400,('Service Duration by unit'!$A$1:$A$400=$J6)*('Service Duration by unit'!$C$1:$C$400=_xlfn.MINIFS('Service Duration by unit'!$C$1:$C$400,'Service Duration by unit'!$A$1:$A$400,$J6,'Service Duration by unit'!$C$1:$C$400,">="&IF($H6=$M$4,N$4,N$3)))),1))*$L6/3600)*(1+$M6)} -> 0 | BT6: {=(IF($H6=$M$4,N$4*$I6,N$3*$I6)+(INDEX(_xlfn._xlws.FILTER('Service Duration by unit'!$D$1:$D$400,('Service Duration by unit'!$A$1:$A$400=$J6)*('Service Duration by unit'!$C$1:$C$400=_xlfn.MINIFS('Service Duration by unit'!$C$1:$C$400,'Service Duration by unit'!$A$1:$A$400,$J6,'Service Duration by unit'!$C$1:$C$400,">="&IF($H6=$M$4,N$4,N$3)))),1))*$L6/3600)*(1+$M6)} -> 0 | BU6: {=(IF($H6=$M$4,N$4*$I6,N$3*$I6)+(INDEX(_xlfn._xlws.FILTER('Service Duration by unit'!$D$1:$D$400,('Service Duration by unit'!$A$1:$A$400=$J6)*('Service Duration by unit'!$C$1:$C$400=_xlfn.MINIFS('Service Duration by unit'!$C$1:$C$400,'Service Duration by unit'!$A$1:$A$400,$J6,'Service Duration by unit'!$C$1:$C$400,">="&IF($H6=$M$4,N$4,N$3)))),1))*$L6/3600)*(1+$M6)} -> 0 | BV6: {=(IF($H6=$M$4,N$4*$I6,N$3*$I6)+(INDEX(_xlfn._xlws.FILTER('Service Duration by unit'!$D$1:$D$400,('Service Duration by unit'!$A$1:$A$400=$J6)*('Service Duration by unit'!$C$1:$C$400=_xlfn.MINIFS('Service Duration by unit'!$C$1:$C$400,'Service Duration by unit'!$A$1:$A$400,$J6,'Service Duration by unit'!$C$1:$C$400,">="&IF($H6=$M$4,N$4,N$3)))),1))*$L6/3600)*(1+$M6)} -> 0 | BW6: {=(IF($H6=$M$4,N$4*$I6,N$3*$I6)+(INDEX(_xlfn._xlws.FILTER('Service Duration by unit'!$D$1:$D$400,('Service Duration by unit'!$A$1:$A$400=$J6)*('Service Duration by unit'!$C$1:$C$400=_xlfn.MINIFS('Service Duration by unit'!$C$1:$C$400,'Service Duration by unit'!$A$1:$A$400,$J6,'Service Duration by unit'!$C$1:$C$400,">="&IF($H6=$M$4,N$4,N$3)))),1))*$L6/3600)*(1+$M6)} -> 0 | BX6: {=(IF($H6=$M$4,N$4*$I6,N$3*$I6)+(INDEX(_xlfn._xlws.FILTER('Service Duration by unit'!$D$1:$D$400,('Service Duration by unit'!$A$1:$A$400=$J6)*('Service Duration by unit'!$C$1:$C$400=_xlfn.MINIFS('Service Duration by unit'!$C$1:$C$400,'Service Duration by unit'!$A$1:$A$400,$J6,'Service Duration by unit'!$C$1:$C$400,">="&IF($H6=$M$4,N$4,N$3)))),1))*$L6/3600)*(1+$M6)} -> 0 | BY6: {=(IF($H6=$M$4,N$4*$I6,N$3*$I6)+(INDEX(_xlfn._xlws.FILTER('Service Duration by unit'!$D$1:$D$400,('Service Duration by unit'!$A$1:$A$400=$J6)*('Service Duration by unit'!$C$1:$C$400=_xlfn.MINIFS('Service Duration by unit'!$C$1:$C$400,'Service Duration by unit'!$A$1:$A$400,$J6,'Service Duration by unit'!$C$1:$C$400,">="&IF($H6=$M$4,N$4,N$3)))),1))*$L6/3600)*(1+$M6)} -> 0 | BZ6: {=(IF($H6=$M$4,N$4*$I6,N$3*$I6)+(INDEX(_xlfn._xlws.FILTER('Service Duration by unit'!$D$1:$D$400,('Service Duration by unit'!$A$1:$A$400=$J6)*('Service Duration by unit'!$C$1:$C$400=_xlfn.MINIFS('Service Duration by unit'!$C$1:$C$400,'Service Duration by unit'!$A$1:$A$400,$J6,'Service Duration by unit'!$C$1:$C$400,">="&IF($H6=$M$4,N$4,N$3)))),1))*$L6/3600)*(1+$M6)} -> 0 | CA6: {=(IF($H6=$M$4,N$4*$I6,N$3*$I6)+(INDEX(_xlfn._xlws.FILTER('Service Duration by unit'!$D$1:$D$400,('Service Duration by unit'!$A$1:$A$400=$J6)*('Service Duration by unit'!$C$1:$C$400=_xlfn.MINIFS('Service Duration by unit'!$C$1:$C$400,'Service Duration by unit'!$A$1:$A$400,$J6,'Service Duration by unit'!$C$1:$C$400,">="&IF($H6=$M$4,N$4,N$3)))),1))*$L6/3600)*(1+$M6)} -> 0 | CB6: {=(IF($H6=$M$4,N$4*$I6,N$3*$I6)+(INDEX(_xlfn._xlws.FILTER('Service Duration by unit'!$D$1:$D$400,('Service Duration by unit'!$A$1:$A$400=$J6)*('Service Duration by unit'!$C$1:$C$400=_xlfn.MINIFS('Service Duration by unit'!$C$1:$C$400,'Service Duration by unit'!$A$1:$A$400,$J6,'Service Duration by unit'!$C$1:$C$400,">="&IF($H6=$M$4,N$4,N$3)))),1))*$L6/3600)*(1+$M6)} -> 0 | CC6: {=(IF($H6=$M$4,N$4*$I6,N$3*$I6)+(INDEX(_xlfn._xlws.FILTER('Service Duration by unit'!$D$1:$D$400,('Service Duration by unit'!$A$1:$A$400=$J6)*('Service Duration by unit'!$C$1:$C$400=_xlfn.MINIFS('Service Duration by unit'!$C$1:$C$400,'Service Duration by unit'!$A$1:$A$400,$J6,'Service Duration by unit'!$C$1:$C$400,">="&IF($H6=$M$4,N$4,N$3)))),1))*$L6/3600)*(1+$M6)} -> 0 | CD6: {=(IF($H6=$M$4,N$4*$I6,N$3*$I6)+(INDEX(_xlfn._xlws.FILTER('Service Duration by unit'!$D$1:$D$400,('Service Duration by unit'!$A$1:$A$400=$J6)*('Service Duration by unit'!$C$1:$C$400=_xlfn.MINIFS('Service Duration by unit'!$C$1:$C$400,'Service Duration by unit'!$A$1:$A$400,$J6,'Service Duration by unit'!$C$1:$C$400,">="&IF($H6=$M$4,N$4,N$3)))),1))*$L6/3600)*(1+$M6)} -> 0 | CE6: {=(IF($H6=$M$4,N$4*$I6,N$3*$I6)+(INDEX(_xlfn._xlws.FILTER('Service Duration by unit'!$D$1:$D$400,('Service Duration by unit'!$A$1:$A$400=$J6)*('Service Duration by unit'!$C$1:$C$400=_xlfn.MINIFS('Service Duration by unit'!$C$1:$C$400,'Service Duration by unit'!$A$1:$A$400,$J6,'Service Duration by unit'!$C$1:$C$400,">="&IF($H6=$M$4,N$4,N$3)))),1))*$L6/3600)*(1+$M6)} -> 0 | CF6: {=(IF($H6=$M$4,N$4*$I6,N$3*$I6)+(INDEX(_xlfn._xlws.FILTER('Service Duration by unit'!$D$1:$D$400,('Service Duration by unit'!$A$1:$A$400=$J6)*('Service Duration by unit'!$C$1:$C$400=_xlfn.MINIFS('Service Duration by unit'!$C$1:$C$400,'Service Duration by unit'!$A$1:$A$400,$J6,'Service Duration by unit'!$C$1:$C$400,">="&IF($H6=$M$4,N$4,N$3)))),1))*$L6/3600)*(1+$M6)} -> 0 | CG6: {=(IF($H6=$M$4,N$4*$I6,N$3*$I6)+(INDEX(_xlfn._xlws.FILTER('Service Duration by unit'!$D$1:$D$400,('Service Duration by unit'!$A$1:$A$400=$J6)*('Service Duration by unit'!$C$1:$C$400=_xlfn.MINIFS('Service Duration by unit'!$C$1:$C$400,'Service Duration by unit'!$A$1:$A$400,$J6,'Service Duration by unit'!$C$1:$C$400,">="&IF($H6=$M$4,N$4,N$3)))),1))*$L6/3600)*(1+$M6)} -> 0 | CH6: {=(IF($H6=$M$4,N$4*$I6,N$3*$I6)+(INDEX(_xlfn._xlws.FILTER('Service Duration by unit'!$D$1:$D$400,('Service Duration by unit'!$A$1:$A$400=$J6)*('Service Duration by unit'!$C$1:$C$400=_xlfn.MINIFS('Service Duration by unit'!$C$1:$C$400,'Service Duration by unit'!$A$1:$A$400,$J6,'Service Duration by unit'!$C$1:$C$400,">="&IF($H6=$M$4,N$4,N$3)))),1))*$L6/3600)*(1+$M6)} -> 0 | CI6: {=(IF($H6=$M$4,N$4*$I6,N$3*$I6)+(INDEX(_xlfn._xlws.FILTER('Service Duration by unit'!$D$1:$D$400,('Service Duration by unit'!$A$1:$A$400=$J6)*('Service Duration by unit'!$C$1:$C$400=_xlfn.MINIFS('Service Duration by unit'!$C$1:$C$400,'Service Duration by unit'!$A$1:$A$400,$J6,'Service Duration by unit'!$C$1:$C$400,">="&IF($H6=$M$4,N$4,N$3)))),1))*$L6/3600)*(1+$M6)} -> 0 | CJ6: {=(IF($H6=$M$4,N$4*$I6,N$3*$I6)+(INDEX(_xlfn._xlws.FILTER('Service Duration by unit'!$D$1:$D$400,('Service Duration by unit'!$A$1:$A$400=$J6)*('Service Duration by unit'!$C$1:$C$400=_xlfn.MINIFS('Service Duration by unit'!$C$1:$C$400,'Service Duration by unit'!$A$1:$A$400,$J6,'Service Duration by unit'!$C$1:$C$400,">="&IF($H6=$M$4,N$4,N$3)))),1))*$L6/3600)*(1+$M6)} -> 0 | CK6: {=(IF($H6=$M$4,N$4*$I6,N$3*$I6)+(INDEX(_xlfn._xlws.FILTER('Service Duration by unit'!$D$1:$D$400,('Service Duration by unit'!$A$1:$A$400=$J6)*('Service Duration by unit'!$C$1:$C$400=_xlfn.MINIFS('Service Duration by unit'!$C$1:$C$400,'Service Duration by unit'!$A$1:$A$400,$J6,'Service Duration by unit'!$C$1:$C$400,">="&IF($H6=$M$4,N$4,N$3)))),1))*$L6/3600)*(1+$M6)} -> 0 | CL6: {=(IF($H6=$M$4,N$4*$I6,N$3*$I6)+(INDEX(_xlfn._xlws.FILTER('Service Duration by unit'!$D$1:$D$400,('Service Duration by unit'!$A$1:$A$400=$J6)*('Service Duration by unit'!$C$1:$C$400=_xlfn.MINIFS('Service Duration by unit'!$C$1:$C$400,'Service Duration by unit'!$A$1:$A$400,$J6,'Service Duration by unit'!$C$1:$C$400,">="&IF($H6=$M$4,N$4,N$3)))),1))*$L6/3600)*(1+$M6)} -> 0 | CM6: {=(IF($H6=$M$4,N$4*$I6,N$3*$I6)+(INDEX(_xlfn._xlws.FILTER('Service Duration by unit'!$D$1:$D$400,('Service Duration by unit'!$A$1:$A$400=$J6)*('Service Duration by unit'!$C$1:$C$400=_xlfn.MINIFS('Service Duration by unit'!$C$1:$C$400,'Service Duration by unit'!$A$1:$A$400,$J6,'Service Duration by unit'!$C$1:$C$400,">="&IF($H6=$M$4,N$4,N$3)))),1))*$L6/3600)*(1+$M6)} -> 0 | CN6: {=(IF($H6=$M$4,N$4*$I6,N$3*$I6)+(INDEX(_xlfn._xlws.FILTER('Service Duration by unit'!$D$1:$D$400,('Service Duration by unit'!$A$1:$A$400=$J6)*('Service Duration by unit'!$C$1:$C$400=_xlfn.MINIFS('Service Duration by unit'!$C$1:$C$400,'Service Duration by unit'!$A$1:$A$400,$J6,'Service Duration by unit'!$C$1:$C$400,">="&IF($H6=$M$4,N$4,N$3)))),1))*$L6/3600)*(1+$M6)} -> 0 | CO6: {=(IF($H6=$M$4,N$4*$I6,N$3*$I6)+(INDEX(_xlfn._xlws.FILTER('Service Duration by unit'!$D$1:$D$400,('Service Duration by unit'!$A$1:$A$400=$J6)*('Service Duration by unit'!$C$1:$C$400=_xlfn.MINIFS('Service Duration by unit'!$C$1:$C$400,'Service Duration by unit'!$A$1:$A$400,$J6,'Service Duration by unit'!$C$1:$C$400,">="&IF($H6=$M$4,N$4,N$3)))),1))*$L6/3600)*(1+$M6)} -> 0 | CP6: {=(IF($H6=$M$4,N$4*$I6,N$3*$I6)+(INDEX(_xlfn._xlws.FILTER('Service Duration by unit'!$D$1:$D$400,('Service Duration by unit'!$A$1:$A$400=$J6)*('Service Duration by unit'!$C$1:$C$400=_xlfn.MINIFS('Service Duration by unit'!$C$1:$C$400,'Service Duration by unit'!$A$1:$A$400,$J6,'Service Duration by unit'!$C$1:$C$400,">="&IF($H6=$M$4,N$4,N$3)))),1))*$L6/3600)*(1+$M6)} -> 0 | CQ6: {=(IF($H6=$M$4,N$4*$I6,N$3*$I6)+(INDEX(_xlfn._xlws.FILTER('Service Duration by unit'!$D$1:$D$400,('Service Duration by unit'!$A$1:$A$400=$J6)*('Service Duration by unit'!$C$1:$C$400=_xlfn.MINIFS('Service Duration by unit'!$C$1:$C$400,'Service Duration by unit'!$A$1:$A$400,$J6,'Service Duration by unit'!$C$1:$C$400,">="&IF($H6=$M$4,N$4,N$3)))),1))*$L6/3600)*(1+$M6)} -> 0 | CR6: {=(IF($H6=$M$4,N$4*$I6,N$3*$I6)+(INDEX(_xlfn._xlws.FILTER('Service Duration by unit'!$D$1:$D$400,('Service Duration by unit'!$A$1:$A$400=$J6)*('Service Duration by unit'!$C$1:$C$400=_xlfn.MINIFS('Service Duration by unit'!$C$1:$C$400,'Service Duration by unit'!$A$1:$A$400,$J6,'Service Duration by unit'!$C$1:$C$400,">="&IF($H6=$M$4,N$4,N$3)))),1))*$L6/3600)*(1+$M6)} -> 0 | CS6: {=(IF($H6=$M$4,N$4*$I6,N$3*$I6)+(INDEX(_xlfn._xlws.FILTER('Service Duration by unit'!$D$1:$D$400,('Service Duration by unit'!$A$1:$A$400=$J6)*('Service Duration by unit'!$C$1:$C$400=_xlfn.MINIFS('Service Duration by unit'!$C$1:$C$400,'Service Duration by unit'!$A$1:$A$400,$J6,'Service Duration by unit'!$C$1:$C$400,">="&IF($H6=$M$4,N$4,N$3)))),1))*$L6/3600)*(1+$M6)} -> 0 | CT6: {=(IF($H6=$M$4,N$4*$I6,N$3*$I6)+(INDEX(_xlfn._xlws.FILTER('Service Duration by unit'!$D$1:$D$400,('Service Duration by unit'!$A$1:$A$400=$J6)*('Service Duration by unit'!$C$1:$C$400=_xlfn.MINIFS('Service Duration by unit'!$C$1:$C$400,'Service Duration by unit'!$A$1:$A$400,$J6,'Service Duration by unit'!$C$1:$C$400,">="&IF($H6=$M$4,N$4,N$3)))),1))*$L6/3600)*(1+$M6)} -> 0 | CU6: {=(IF($H6=$M$4,N$4*$I6,N$3*$I6)+(INDEX(_xlfn._xlws.FILTER('Service Duration by unit'!$D$1:$D$400,('Service Duration by unit'!$A$1:$A$400=$J6)*('Service Duration by unit'!$C$1:$C$400=_xlfn.MINIFS('Service Duration by unit'!$C$1:$C$400,'Service Duration by unit'!$A$1:$A$400,$J6,'Service Duration by unit'!$C$1:$C$400,">="&IF($H6=$M$4,N$4,N$3)))),1))*$L6/3600)*(1+$M6)} -> 0 | CV6: {=(IF($H6=$M$4,N$4*$I6,N$3*$I6)+(INDEX(_xlfn._xlws.FILTER('Service Duration by unit'!$D$1:$D$400,('Service Duration by unit'!$A$1:$A$400=$J6)*('Service Duration by unit'!$C$1:$C$400=_xlfn.MINIFS('Service Duration by unit'!$C$1:$C$400,'Service Duration by unit'!$A$1:$A$400,$J6,'Service Duration by unit'!$C$1:$C$400,">="&IF($H6=$M$4,N$4,N$3)))),1))*$L6/3600)*(1+$M6)} -> 0 | CW6: {=(IF($H6=$M$4,N$4*$I6,N$3*$I6)+(INDEX(_xlfn._xlws.FILTER('Service Duration by unit'!$D$1:$D$400,('Service Duration by unit'!$A$1:$A$400=$J6)*('Service Duration by unit'!$C$1:$C$400=_xlfn.MINIFS('Service Duration by unit'!$C$1:$C$400,'Service Duration by unit'!$A$1:$A$400,$J6,'Service Duration by unit'!$C$1:$C$400,">="&IF($H6=$M$4,N$4,N$3)))),1))*$L6/3600)*(1+$M6)} -> 0 | CX6: {=(IF($H6=$M$4,N$4*$I6,N$3*$I6)+(INDEX(_xlfn._xlws.FILTER('Service Duration by unit'!$D$1:$D$400,('Service Duration by unit'!$A$1:$A$400=$J6)*('Service Duration by unit'!$C$1:$C$400=_xlfn.MINIFS('Service Duration by unit'!$C$1:$C$400,'Service Duration by unit'!$A$1:$A$400,$J6,'Service Duration by unit'!$C$1:$C$400,">="&IF($H6=$M$4,N$4,N$3)))),1))*$L6/3600)*(1+$M6)} -> 0 | CY6: {=(IF($H6=$M$4,N$4*$I6,N$3*$I6)+(INDEX(_xlfn._xlws.FILTER('Service Duration by unit'!$D$1:$D$400,('Service Duration by unit'!$A$1:$A$400=$J6)*('Service Duration by unit'!$C$1:$C$400=_xlfn.MINIFS('Service Duration by unit'!$C$1:$C$400,'Service Duration by unit'!$A$1:$A$400,$J6,'Service Duration by unit'!$C$1:$C$400,">="&IF($H6=$M$4,N$4,N$3)))),1))*$L6/3600)*(1+$M6)} -> 0 | CZ6: {=(IF($H6=$M$4,N$4*$I6,N$3*$I6)+(INDEX(_xlfn._xlws.FILTER('Service Duration by unit'!$D$1:$D$400,('Service Duration by unit'!$A$1:$A$400=$J6)*('Service Duration by unit'!$C$1:$C$400=_xlfn.MINIFS('Service Duration by unit'!$C$1:$C$400,'Service Duration by unit'!$A$1:$A$400,$J6,'Service Duration by unit'!$C$1:$C$400,">="&IF($H6=$M$4,N$4,N$3)))),1))*$L6/3600)*(1+$M6)} -> 0 | DA6: {=(IF($H6=$M$4,N$4*$I6,N$3*$I6)+(INDEX(_xlfn._xlws.FILTER('Service Duration by unit'!$D$1:$D$400,('Service Duration by unit'!$A$1:$A$400=$J6)*('Service Duration by unit'!$C$1:$C$400=_xlfn.MINIFS('Service Duration by unit'!$C$1:$C$400,'Service Duration by unit'!$A$1:$A$400,$J6,'Service Duration by unit'!$C$1:$C$400,">="&IF($H6=$M$4,N$4,N$3)))),1))*$L6/3600)*(1+$M6)} -> 0 | DB6: {=(IF($H6=$M$4,N$4*$I6,N$3*$I6)+(INDEX(_xlfn._xlws.FILTER('Service Duration by unit'!$D$1:$D$400,('Service Duration by unit'!$A$1:$A$400=$J6)*('Service Duration by unit'!$C$1:$C$400=_xlfn.MINIFS('Service Duration by unit'!$C$1:$C$400,'Service Duration by unit'!$A$1:$A$400,$J6,'Service Duration by unit'!$C$1:$C$400,">="&IF($H6=$M$4,N$4,N$3)))),1))*$L6/3600)*(1+$M6)} -> 0 | DC6: {=(IF($H6=$M$4,N$4*$I6,N$3*$I6)+(INDEX(_xlfn._xlws.FILTER('Service Duration by unit'!$D$1:$D$400,('Service Duration by unit'!$A$1:$A$400=$J6)*('Service Duration by unit'!$C$1:$C$400=_xlfn.MINIFS('Service Duration by unit'!$C$1:$C$400,'Service Duration by unit'!$A$1:$A$400,$J6,'Service Duration by unit'!$C$1:$C$400,">="&IF($H6=$M$4,N$4,N$3)))),1))*$L6/3600)*(1+$M6)} -> 0 | DD6: {=(IF($H6=$M$4,N$4*$I6,N$3*$I6)+(INDEX(_xlfn._xlws.FILTER('Service Duration by unit'!$D$1:$D$400,('Service Duration by unit'!$A$1:$A$400=$J6)*('Service Duration by unit'!$C$1:$C$400=_xlfn.MINIFS('Service Duration by unit'!$C$1:$C$400,'Service Duration by unit'!$A$1:$A$400,$J6,'Service Duration by unit'!$C$1:$C$400,">="&IF($H6=$M$4,N$4,N$3)))),1))*$L6/3600)*(1+$M6)} -> 0 | DE6: {=(IF($H6=$M$4,N$4*$I6,N$3*$I6)+(INDEX(_xlfn._xlws.FILTER('Service Duration by unit'!$D$1:$D$400,('Service Duration by unit'!$A$1:$A$400=$J6)*('Service Duration by unit'!$C$1:$C$400=_xlfn.MINIFS('Service Duration by unit'!$C$1:$C$400,'Service Duration by unit'!$A$1:$A$400,$J6,'Service Duration by unit'!$C$1:$C$400,">="&IF($H6=$M$4,N$4,N$3)))),1))*$L6/3600)*(1+$M6)} -> 0 | DF6: {=(IF($H6=$M$4,N$4*$I6,N$3*$I6)+(INDEX(_xlfn._xlws.FILTER('Service Duration by unit'!$D$1:$D$400,('Service Duration by unit'!$A$1:$A$400=$J6)*('Service Duration by unit'!$C$1:$C$400=_xlfn.MINIFS('Service Duration by unit'!$C$1:$C$400,'Service Duration by unit'!$A$1:$A$400,$J6,'Service Duration by unit'!$C$1:$C$400,">="&IF($H6=$M$4,N$4,N$3)))),1))*$L6/3600)*(1+$M6)} -> 0 | DG6: {=(IF($H6=$M$4,N$4*$I6,N$3*$I6)+(INDEX(_xlfn._xlws.FILTER('Service Duration by unit'!$D$1:$D$400,('Service Duration by unit'!$A$1:$A$400=$J6)*('Service Duration by unit'!$C$1:$C$400=_xlfn.MINIFS('Service Duration by unit'!$C$1:$C$400,'Service Duration by unit'!$A$1:$A$400,$J6,'Service Duration by unit'!$C$1:$C$400,">="&IF($H6=$M$4,N$4,N$3)))),1))*$L6/3600)*(1+$M6)} -> 0 | DH6: {=(IF($H6=$M$4,N$4*$I6,N$3*$I6)+(INDEX(_xlfn._xlws.FILTER('Service Duration by unit'!$D$1:$D$400,('Service Duration by unit'!$A$1:$A$400=$J6)*('Service Duration by unit'!$C$1:$C$400=_xlfn.MINIFS('Service Duration by unit'!$C$1:$C$400,'Service Duration by unit'!$A$1:$A$400,$J6,'Service Duration by unit'!$C$1:$C$400,">="&IF($H6=$M$4,N$4,N$3)))),1))*$L6/3600)*(1+$M6)} -> 0 | DI6: {=(IF($H6=$M$4,N$4*$I6,N$3*$I6)+(INDEX(_xlfn._xlws.FILTER('Service Duration by unit'!$D$1:$D$400,('Service Duration by unit'!$A$1:$A$400=$J6)*('Service Duration by unit'!$C$1:$C$400=_xlfn.MINIFS('Service Duration by unit'!$C$1:$C$400,'Service Duration by unit'!$A$1:$A$400,$J6,'Service Duration by unit'!$C$1:$C$400,">="&IF($H6=$M$4,N$4,N$3)))),1))*$L6/3600)*(1+$M6)} -> 0 | DJ6: {=(IF($H6=$M$4,N$4*$I6,N$3*$I6)+(INDEX(_xlfn._xlws.FILTER('Service Duration by unit'!$D$1:$D$400,('Service Duration by unit'!$A$1:$A$400=$J6)*('Service Duration by unit'!$C$1:$C$400=_xlfn.MINIFS('Service Duration by unit'!$C$1:$C$400,'Service Duration by unit'!$A$1:$A$400,$J6,'Service Duration by unit'!$C$1:$C$400,">="&IF($H6=$M$4,N$4,N$3)))),1))*$L6/3600)*(1+$M6)} -> 0 | DK6: {=(IF($H6=$M$4,N$4*$I6,N$3*$I6)+(INDEX(_xlfn._xlws.FILTER('Service Duration by unit'!$D$1:$D$400,('Service Duration by unit'!$A$1:$A$400=$J6)*('Service Duration by unit'!$C$1:$C$400=_xlfn.MINIFS('Service Duration by unit'!$C$1:$C$400,'Service Duration by unit'!$A$1:$A$400,$J6,'Service Duration by unit'!$C$1:$C$400,">="&IF($H6=$M$4,N$4,N$3)))),1))*$L6/3600)*(1+$M6)} -> 0 | DL6: {=(IF($H6=$M$4,N$4*$I6,N$3*$I6)+(INDEX(_xlfn._xlws.FILTER('Service Duration by unit'!$D$1:$D$400,('Service Duration by unit'!$A$1:$A$400=$J6)*('Service Duration by unit'!$C$1:$C$400=_xlfn.MINIFS('Service Duration by unit'!$C$1:$C$400,'Service Duration by unit'!$A$1:$A$400,$J6,'Service Duration by unit'!$C$1:$C$400,">="&IF($H6=$M$4,N$4,N$3)))),1))*$L6/3600)*(1+$M6)} -> 0 | DM6: {=(IF($H6=$M$4,N$4*$I6,N$3*$I6)+(INDEX(_xlfn._xlws.FILTER('Service Duration by unit'!$D$1:$D$400,('Service Duration by unit'!$A$1:$A$400=$J6)*('Service Duration by unit'!$C$1:$C$400=_xlfn.MINIFS('Service Duration by unit'!$C$1:$C$400,'Service Duration by unit'!$A$1:$A$400,$J6,'Service Duration by unit'!$C$1:$C$400,">="&IF($H6=$M$4,N$4,N$3)))),1))*$L6/3600)*(1+$M6)} -> 0 | DN6: {=(IF($H6=$M$4,N$4*$I6,N$3*$I6)+(INDEX(_xlfn._xlws.FILTER('Service Duration by unit'!$D$1:$D$400,('Service Duration by unit'!$A$1:$A$400=$J6)*('Service Duration by unit'!$C$1:$C$400=_xlfn.MINIFS('Service Duration by unit'!$C$1:$C$400,'Service Duration by unit'!$A$1:$A$400,$J6,'Service Duration by unit'!$C$1:$C$400,">="&IF($H6=$M$4,N$4,N$3)))),1))*$L6/3600)*(1+$M6)} -> 0 | DO6: {=(IF($H6=$M$4,N$4*$I6,N$3*$I6)+(INDEX(_xlfn._xlws.FILTER('Service Duration by unit'!$D$1:$D$400,('Service Duration by unit'!$A$1:$A$400=$J6)*('Service Duration by unit'!$C$1:$C$400=_xlfn.MINIFS('Service Duration by unit'!$C$1:$C$400,'Service Duration by unit'!$A$1:$A$400,$J6,'Service Duration by unit'!$C$1:$C$400,">="&IF($H6=$M$4,N$4,N$3)))),1))*$L6/3600)*(1+$M6)} -> 0 | DP6: {=(IF($H6=$M$4,N$4*$I6,N$3*$I6)+(INDEX(_xlfn._xlws.FILTER('Service Duration by unit'!$D$1:$D$400,('Service Duration by unit'!$A$1:$A$400=$J6)*('Service Duration by unit'!$C$1:$C$400=_xlfn.MINIFS('Service Duration by unit'!$C$1:$C$400,'Service Duration by unit'!$A$1:$A$400,$J6,'Service Duration by unit'!$C$1:$C$400,">="&IF($H6=$M$4,N$4,N$3)))),1))*$L6/3600)*(1+$M6)} -> 0 | DQ6: {=(IF($H6=$M$4,N$4*$I6,N$3*$I6)+(INDEX(_xlfn._xlws.FILTER('Service Duration by unit'!$D$1:$D$400,('Service Duration by unit'!$A$1:$A$400=$J6)*('Service Duration by unit'!$C$1:$C$400=_xlfn.MINIFS('Service Duration by unit'!$C$1:$C$400,'Service Duration by unit'!$A$1:$A$400,$J6,'Service Duration by unit'!$C$1:$C$400,">="&IF($H6=$M$4,N$4,N$3)))),1))*$L6/3600)*(1+$M6)} -> 0 | DR6: {=(IF($H6=$M$4,N$4*$I6,N$3*$I6)+(INDEX(_xlfn._xlws.FILTER('Service Duration by unit'!$D$1:$D$400,('Service Duration by unit'!$A$1:$A$400=$J6)*('Service Duration by unit'!$C$1:$C$400=_xlfn.MINIFS('Service Duration by unit'!$C$1:$C$400,'Service Duration by unit'!$A$1:$A$400,$J6,'Service Duration by unit'!$C$1:$C$400,">="&IF($H6=$M$4,N$4,N$3)))),1))*$L6/3600)*(1+$M6)} -> 0 | DS6: {=(IF($H6=$M$4,N$4*$I6,N$3*$I6)+(INDEX(_xlfn._xlws.FILTER('Service Duration by unit'!$D$1:$D$400,('Service Duration by unit'!$A$1:$A$400=$J6)*('Service Duration by unit'!$C$1:$C$400=_xlfn.MINIFS('Service Duration by unit'!$C$1:$C$400,'Service Duration by unit'!$A$1:$A$400,$J6,'Service Duration by unit'!$C$1:$C$400,">="&IF($H6=$M$4,N$4,N$3)))),1))*$L6/3600)*(1+$M6)} -> 0 | DT6: {=(IF($H6=$M$4,N$4*$I6,N$3*$I6)+(INDEX(_xlfn._xlws.FILTER('Service Duration by unit'!$D$1:$D$400,('Service Duration by unit'!$A$1:$A$400=$J6)*('Service Duration by unit'!$C$1:$C$400=_xlfn.MINIFS('Service Duration by unit'!$C$1:$C$400,'Service Duration by unit'!$A$1:$A$400,$J6,'Service Duration by unit'!$C$1:$C$400,">="&IF($H6=$M$4,N$4,N$3)))),1))*$L6/3600)*(1+$M6)} -> 0 | DU6: {=(IF($H6=$M$4,N$4*$I6,N$3*$I6)+(INDEX(_xlfn._xlws.FILTER('Service Duration by unit'!$D$1:$D$400,('Service Duration by unit'!$A$1:$A$400=$J6)*('Service Duration by unit'!$C$1:$C$400=_xlfn.MINIFS('Service Duration by unit'!$C$1:$C$400,'Service Duration by unit'!$A$1:$A$400,$J6,'Service Duration by unit'!$C$1:$C$400,">="&IF($H6=$M$4,N$4,N$3)))),1))*$L6/3600)*(1+$M6)} -> 0 | DV6: {=(IF($H6=$M$4,N$4*$I6,N$3*$I6)+(INDEX(_xlfn._xlws.FILTER('Service Duration by unit'!$D$1:$D$400,('Service Duration by unit'!$A$1:$A$400=$J6)*('Service Duration by unit'!$C$1:$C$400=_xlfn.MINIFS('Service Duration by unit'!$C$1:$C$400,'Service Duration by unit'!$A$1:$A$400,$J6,'Service Duration by unit'!$C$1:$C$400,">="&IF($H6=$M$4,N$4,N$3)))),1))*$L6/3600)*(1+$M6)} -> 0 | DW6: {=(IF($H6=$M$4,N$4*$I6,N$3*$I6)+(INDEX(_xlfn._xlws.FILTER('Service Duration by unit'!$D$1:$D$400,('Service Duration by unit'!$A$1:$A$400=$J6)*('Service Duration by unit'!$C$1:$C$400=_xlfn.MINIFS('Service Duration by unit'!$C$1:$C$400,'Service Duration by unit'!$A$1:$A$400,$J6,'Service Duration by unit'!$C$1:$C$400,">="&IF($H6=$M$4,N$4,N$3)))),1))*$L6/3600)*(1+$M6)} -> 0 | DX6: {=(IF($H6=$M$4,N$4*$I6,N$3*$I6)+(INDEX(_xlfn._xlws.FILTER('Service Duration by unit'!$D$1:$D$400,('Service Duration by unit'!$A$1:$A$400=$J6)*('Service Duration by unit'!$C$1:$C$400=_xlfn.MINIFS('Service Duration by unit'!$C$1:$C$400,'Service Duration by unit'!$A$1:$A$400,$J6,'Service Duration by unit'!$C$1:$C$400,">="&IF($H6=$M$4,N$4,N$3)))),1))*$L6/3600)*(1+$M6)} -> 0 | DY6: {=(IF($H6=$M$4,N$4*$I6,N$3*$I6)+(INDEX(_xlfn._xlws.FILTER('Service Duration by unit'!$D$1:$D$400,('Service Duration by unit'!$A$1:$A$400=$J6)*('Service Duration by unit'!$C$1:$C$400=_xlfn.MINIFS('Service Duration by unit'!$C$1:$C$400,'Service Duration by unit'!$A$1:$A$400,$J6,'Service Duration by unit'!$C$1:$C$400,">="&IF($H6=$M$4,N$4,N$3)))),1))*$L6/3600)*(1+$M6)} -> 0 | DZ6: {=(IF($H6=$M$4,N$4*$I6,N$3*$I6)+(INDEX(_xlfn._xlws.FILTER('Service Duration by unit'!$D$1:$D$400,('Service Duration by unit'!$A$1:$A$400=$J6)*('Service Duration by unit'!$C$1:$C$400=_xlfn.MINIFS('Service Duration by unit'!$C$1:$C$400,'Service Duration by unit'!$A$1:$A$400,$J6,'Service Duration by unit'!$C$1:$C$400,">="&IF($H6=$M$4,N$4,N$3)))),1))*$L6/3600)*(1+$M6)} -> 0 | EA6: {=(IF($H6=$M$4,N$4*$I6,N$3*$I6)+(INDEX(_xlfn._xlws.FILTER('Service Duration by unit'!$D$1:$D$400,('Service Duration by unit'!$A$1:$A$400=$J6)*('Service Duration by unit'!$C$1:$C$400=_xlfn.MINIFS('Service Duration by unit'!$C$1:$C$400,'Service Duration by unit'!$A$1:$A$400,$J6,'Service Duration by unit'!$C$1:$C$400,">="&IF($H6=$M$4,N$4,N$3)))),1))*$L6/3600)*(1+$M6)} -> 0 | EB6: {=(IF($H6=$M$4,N$4*$I6,N$3*$I6)+(INDEX(_xlfn._xlws.FILTER('Service Duration by unit'!$D$1:$D$400,('Service Duration by unit'!$A$1:$A$400=$J6)*('Service Duration by unit'!$C$1:$C$400=_xlfn.MINIFS('Service Duration by unit'!$C$1:$C$400,'Service Duration by unit'!$A$1:$A$400,$J6,'Service Duration by unit'!$C$1:$C$400,">="&IF($H6=$M$4,N$4,N$3)))),1))*$L6/3600)*(1+$M6)} -> 0 | EC6: {=(IF($H6=$M$4,N$4*$I6,N$3*$I6)+(INDEX(_xlfn._xlws.FILTER('Service Duration by unit'!$D$1:$D$400,('Service Duration by unit'!$A$1:$A$400=$J6)*('Service Duration by unit'!$C$1:$C$400=_xlfn.MINIFS('Service Duration by unit'!$C$1:$C$400,'Service Duration by unit'!$A$1:$A$400,$J6,'Service Duration by unit'!$C$1:$C$400,">="&IF($H6=$M$4,N$4,N$3)))),1))*$L6/3600)*(1+$M6)} -> 0 | ED6: {=(IF($H6=$M$4,N$4*$I6,N$3*$I6)+(INDEX(_xlfn._xlws.FILTER('Service Duration by unit'!$D$1:$D$400,('Service Duration by unit'!$A$1:$A$400=$J6)*('Service Duration by unit'!$C$1:$C$400=_xlfn.MINIFS('Service Duration by unit'!$C$1:$C$400,'Service Duration by unit'!$A$1:$A$400,$J6,'Service Duration by unit'!$C$1:$C$400,">="&IF($H6=$M$4,N$4,N$3)))),1))*$L6/3600)*(1+$M6)} -> 0 | EE6: {=(IF($H6=$M$4,N$4*$I6,N$3*$I6)+(INDEX(_xlfn._xlws.FILTER('Service Duration by unit'!$D$1:$D$400,('Service Duration by unit'!$A$1:$A$400=$J6)*('Service Duration by unit'!$C$1:$C$400=_xlfn.MINIFS('Service Duration by unit'!$C$1:$C$400,'Service Duration by unit'!$A$1:$A$400,$J6,'Service Duration by unit'!$C$1:$C$400,">="&IF($H6=$M$4,N$4,N$3)))),1))*$L6/3600)*(1+$M6)} -> 0 | EF6: {=(IF($H6=$M$4,N$4*$I6,N$3*$I6)+(INDEX(_xlfn._xlws.FILTER('Service Duration by unit'!$D$1:$D$400,('Service Duration by unit'!$A$1:$A$400=$J6)*('Service Duration by unit'!$C$1:$C$400=_xlfn.MINIFS('Service Duration by unit'!$C$1:$C$400,'Service Duration by unit'!$A$1:$A$400,$J6,'Service Duration by unit'!$C$1:$C$400,">="&IF($H6=$M$4,N$4,N$3)))),1))*$L6/3600)*(1+$M6)} -> 0 | EG6: {=(IF($H6=$M$4,N$4*$I6,N$3*$I6)+(INDEX(_xlfn._xlws.FILTER('Service Duration by unit'!$D$1:$D$400,('Service Duration by unit'!$A$1:$A$400=$J6)*('Service Duration by unit'!$C$1:$C$400=_xlfn.MINIFS('Service Duration by unit'!$C$1:$C$400,'Service Duration by unit'!$A$1:$A$400,$J6,'Service Duration by unit'!$C$1:$C$400,">="&IF($H6=$M$4,N$4,N$3)))),1))*$L6/3600)*(1+$M6)} -> 0 | EH6: {=(IF($H6=$M$4,N$4*$I6,N$3*$I6)+(INDEX(_xlfn._xlws.FILTER('Service Duration by unit'!$D$1:$D$400,('Service Duration by unit'!$A$1:$A$400=$J6)*('Service Duration by unit'!$C$1:$C$400=_xlfn.MINIFS('Service Duration by unit'!$C$1:$C$400,'Service Duration by unit'!$A$1:$A$400,$J6,'Service Duration by unit'!$C$1:$C$400,">="&IF($H6=$M$4,N$4,N$3)))),1))*$L6/3600)*(1+$M6)} -> 0 | EI6: {=(IF($H6=$M$4,N$4*$I6,N$3*$I6)+(INDEX(_xlfn._xlws.FILTER('Service Duration by unit'!$D$1:$D$400,('Service Duration by unit'!$A$1:$A$400=$J6)*('Service Duration by unit'!$C$1:$C$400=_xlfn.MINIFS('Service Duration by unit'!$C$1:$C$400,'Service Duration by unit'!$A$1:$A$400,$J6,'Service Duration by unit'!$C$1:$C$400,">="&IF($H6=$M$4,N$4,N$3)))),1))*$L6/3600)*(1+$M6)} -> 0 | EJ6: {=(IF($H6=$M$4,N$4*$I6,N$3*$I6)+(INDEX(_xlfn._xlws.FILTER('Service Duration by unit'!$D$1:$D$400,('Service Duration by unit'!$A$1:$A$400=$J6)*('Service Duration by unit'!$C$1:$C$400=_xlfn.MINIFS('Service Duration by unit'!$C$1:$C$400,'Service Duration by unit'!$A$1:$A$400,$J6,'Service Duration by unit'!$C$1:$C$400,">="&IF($H6=$M$4,N$4,N$3)))),1))*$L6/3600)*(1+$M6)} -> 0 | EK6: {=(IF($H6=$M$4,N$4*$I6,N$3*$I6)+(INDEX(_xlfn._xlws.FILTER('Service Duration by unit'!$D$1:$D$400,('Service Duration by unit'!$A$1:$A$400=$J6)*('Service Duration by unit'!$C$1:$C$400=_xlfn.MINIFS('Service Duration by unit'!$C$1:$C$400,'Service Duration by unit'!$A$1:$A$400,$J6,'Service Duration by unit'!$C$1:$C$400,">="&IF($H6=$M$4,N$4,N$3)))),1))*$L6/3600)*(1+$M6)} -> 0 | EL6: {=(IF($H6=$M$4,N$4*$I6,N$3*$I6)+(INDEX(_xlfn._xlws.FILTER('Service Duration by unit'!$D$1:$D$400,('Service Duration by unit'!$A$1:$A$400=$J6)*('Service Duration by unit'!$C$1:$C$400=_xlfn.MINIFS('Service Duration by unit'!$C$1:$C$400,'Service Duration by unit'!$A$1:$A$400,$J6,'Service Duration by unit'!$C$1:$C$400,">="&IF($H6=$M$4,N$4,N$3)))),1))*$L6/3600)*(1+$M6)} -> 0 | EM6: {=(IF($H6=$M$4,N$4*$I6,N$3*$I6)+(INDEX(_xlfn._xlws.FILTER('Service Duration by unit'!$D$1:$D$400,('Service Duration by unit'!$A$1:$A$400=$J6)*('Service Duration by unit'!$C$1:$C$400=_xlfn.MINIFS('Service Duration by unit'!$C$1:$C$400,'Service Duration by unit'!$A$1:$A$400,$J6,'Service Duration by unit'!$C$1:$C$400,">="&IF($H6=$M$4,N$4,N$3)))),1))*$L6/3600)*(1+$M6)} -> 0 | EN6: {=(IF($H6=$M$4,N$4*$I6,N$3*$I6)+(INDEX(_xlfn._xlws.FILTER('Service Duration by unit'!$D$1:$D$400,('Service Duration by unit'!$A$1:$A$400=$J6)*('Service Duration by unit'!$C$1:$C$400=_xlfn.MINIFS('Service Duration by unit'!$C$1:$C$400,'Service Duration by unit'!$A$1:$A$400,$J6,'Service Duration by unit'!$C$1:$C$400,">="&IF($H6=$M$4,N$4,N$3)))),1))*$L6/3600)*(1+$M6)} -> 0 | EO6: {=(IF($H6=$M$4,N$4*$I6,N$3*$I6)+(INDEX(_xlfn._xlws.FILTER('Service Duration by unit'!$D$1:$D$400,('Service Duration by unit'!$A$1:$A$400=$J6)*('Service Duration by unit'!$C$1:$C$400=_xlfn.MINIFS('Service Duration by unit'!$C$1:$C$400,'Service Duration by unit'!$A$1:$A$400,$J6,'Service Duration by unit'!$C$1:$C$400,">="&IF($H6=$M$4,N$4,N$3)))),1))*$L6/3600)*(1+$M6)} -> 0 | EP6: {=(IF($H6=$M$4,N$4*$I6,N$3*$I6)+(INDEX(_xlfn._xlws.FILTER('Service Duration by unit'!$D$1:$D$400,('Service Duration by unit'!$A$1:$A$400=$J6)*('Service Duration by unit'!$C$1:$C$400=_xlfn.MINIFS('Service Duration by unit'!$C$1:$C$400,'Service Duration by unit'!$A$1:$A$400,$J6,'Service Duration by unit'!$C$1:$C$400,">="&IF($H6=$M$4,N$4,N$3)))),1))*$L6/3600)*(1+$M6)} -> 0 | EQ6: {=(IF($H6=$M$4,N$4*$I6,N$3*$I6)+(INDEX(_xlfn._xlws.FILTER('Service Duration by unit'!$D$1:$D$400,('Service Duration by unit'!$A$1:$A$400=$J6)*('Service Duration by unit'!$C$1:$C$400=_xlfn.MINIFS('Service Duration by unit'!$C$1:$C$400,'Service Duration by unit'!$A$1:$A$400,$J6,'Service Duration by unit'!$C$1:$C$400,">="&IF($H6=$M$4,N$4,N$3)))),1))*$L6/3600)*(1+$M6)} -> 0 | ER6: {=(IF($H6=$M$4,N$4*$I6,N$3*$I6)+(INDEX(_xlfn._xlws.FILTER('Service Duration by unit'!$D$1:$D$400,('Service Duration by unit'!$A$1:$A$400=$J6)*('Service Duration by unit'!$C$1:$C$400=_xlfn.MINIFS('Service Duration by unit'!$C$1:$C$400,'Service Duration by unit'!$A$1:$A$400,$J6,'Service Duration by unit'!$C$1:$C$400,">="&IF($H6=$M$4,N$4,N$3)))),1))*$L6/3600)*(1+$M6)} -> 0 | ES6: {=(IF($H6=$M$4,N$4*$I6,N$3*$I6)+(INDEX(_xlfn._xlws.FILTER('Service Duration by unit'!$D$1:$D$400,('Service Duration by unit'!$A$1:$A$400=$J6)*('Service Duration by unit'!$C$1:$C$400=_xlfn.MINIFS('Service Duration by unit'!$C$1:$C$400,'Service Duration by unit'!$A$1:$A$400,$J6,'Service Duration by unit'!$C$1:$C$400,">="&IF($H6=$M$4,N$4,N$3)))),1))*$L6/3600)*(1+$M6)} -> 0 | ET6: {=(IF($H6=$M$4,N$4*$I6,N$3*$I6)+(INDEX(_xlfn._xlws.FILTER('Service Duration by unit'!$D$1:$D$400,('Service Duration by unit'!$A$1:$A$400=$J6)*('Service Duration by unit'!$C$1:$C$400=_xlfn.MINIFS('Service Duration by unit'!$C$1:$C$400,'Service Duration by unit'!$A$1:$A$400,$J6,'Service Duration by unit'!$C$1:$C$400,">="&IF($H6=$M$4,N$4,N$3)))),1))*$L6/3600)*(1+$M6)} -> 0 | EU6: {=(IF($H6=$M$4,N$4*$I6,N$3*$I6)+(INDEX(_xlfn._xlws.FILTER('Service Duration by unit'!$D$1:$D$400,('Service Duration by unit'!$A$1:$A$400=$J6)*('Service Duration by unit'!$C$1:$C$400=_xlfn.MINIFS('Service Duration by unit'!$C$1:$C$400,'Service Duration by unit'!$A$1:$A$400,$J6,'Service Duration by unit'!$C$1:$C$400,">="&IF($H6=$M$4,N$4,N$3)))),1))*$L6/3600)*(1+$M6)} -> 0 | EV6: {=(IF($H6=$M$4,N$4*$I6,N$3*$I6)+(INDEX(_xlfn._xlws.FILTER('Service Duration by unit'!$D$1:$D$400,('Service Duration by unit'!$A$1:$A$400=$J6)*('Service Duration by unit'!$C$1:$C$400=_xlfn.MINIFS('Service Duration by unit'!$C$1:$C$400,'Service Duration by unit'!$A$1:$A$400,$J6,'Service Duration by unit'!$C$1:$C$400,">="&IF($H6=$M$4,N$4,N$3)))),1))*$L6/3600)*(1+$M6)} -> 0 | EW6: {=(IF($H6=$M$4,N$4*$I6,N$3*$I6)+(INDEX(_xlfn._xlws.FILTER('Service Duration by unit'!$D$1:$D$400,('Service Duration by unit'!$A$1:$A$400=$J6)*('Service Duration by unit'!$C$1:$C$400=_xlfn.MINIFS('Service Duration by unit'!$C$1:$C$400,'Service Duration by unit'!$A$1:$A$400,$J6,'Service Duration by unit'!$C$1:$C$400,">="&IF($H6=$M$4,N$4,N$3)))),1))*$L6/3600)*(1+$M6)} -> 0 | EX6: {=(IF($H6=$M$4,N$4*$I6,N$3*$I6)+(INDEX(_xlfn._xlws.FILTER('Service Duration by unit'!$D$1:$D$400,('Service Duration by unit'!$A$1:$A$400=$J6)*('Service Duration by unit'!$C$1:$C$400=_xlfn.MINIFS('Service Duration by unit'!$C$1:$C$400,'Service Duration by unit'!$A$1:$A$400,$J6,'Service Duration by unit'!$C$1:$C$400,">="&IF($H6=$M$4,N$4,N$3)))),1))*$L6/3600)*(1+$M6)} -> 0 | EY6: {=(IF($H6=$M$4,N$4*$I6,N$3*$I6)+(INDEX(_xlfn._xlws.FILTER('Service Duration by unit'!$D$1:$D$400,('Service Duration by unit'!$A$1:$A$400=$J6)*('Service Duration by unit'!$C$1:$C$400=_xlfn.MINIFS('Service Duration by unit'!$C$1:$C$400,'Service Duration by unit'!$A$1:$A$400,$J6,'Service Duration by unit'!$C$1:$C$400,">="&IF($H6=$M$4,N$4,N$3)))),1))*$L6/3600)*(1+$M6)} -> 0 | EZ6: {=(IF($H6=$M$4,N$4*$I6,N$3*$I6)+(INDEX(_xlfn._xlws.FILTER('Service Duration by unit'!$D$1:$D$400,('Service Duration by unit'!$A$1:$A$400=$J6)*('Service Duration by unit'!$C$1:$C$400=_xlfn.MINIFS('Service Duration by unit'!$C$1:$C$400,'Service Duration by unit'!$A$1:$A$400,$J6,'Service Duration by unit'!$C$1:$C$400,">="&IF($H6=$M$4,N$4,N$3)))),1))*$L6/3600)*(1+$M6)} -> 0 | FA6: {=(IF($H6=$M$4,N$4*$I6,N$3*$I6)+(INDEX(_xlfn._xlws.FILTER('Service Duration by unit'!$D$1:$D$400,('Service Duration by unit'!$A$1:$A$400=$J6)*('Service Duration by unit'!$C$1:$C$400=_xlfn.MINIFS('Service Duration by unit'!$C$1:$C$400,'Service Duration by unit'!$A$1:$A$400,$J6,'Service Duration by unit'!$C$1:$C$400,">="&IF($H6=$M$4,N$4,N$3)))),1))*$L6/3600)*(1+$M6)} -> 0 | FB6: {=(IF($H6=$M$4,N$4*$I6,N$3*$I6)+(INDEX(_xlfn._xlws.FILTER('Service Duration by unit'!$D$1:$D$400,('Service Duration by unit'!$A$1:$A$400=$J6)*('Service Duration by unit'!$C$1:$C$400=_xlfn.MINIFS('Service Duration by unit'!$C$1:$C$400,'Service Duration by unit'!$A$1:$A$400,$J6,'Service Duration by unit'!$C$1:$C$400,">="&IF($H6=$M$4,N$4,N$3)))),1))*$L6/3600)*(1+$M6)} -> 0 | FC6: {=(IF($H6=$M$4,N$4*$I6,N$3*$I6)+(INDEX(_xlfn._xlws.FILTER('Service Duration by unit'!$D$1:$D$400,('Service Duration by unit'!$A$1:$A$400=$J6)*('Service Duration by unit'!$C$1:$C$400=_xlfn.MINIFS('Service Duration by unit'!$C$1:$C$400,'Service Duration by unit'!$A$1:$A$400,$J6,'Service Duration by unit'!$C$1:$C$400,">="&IF($H6=$M$4,N$4,N$3)))),1))*$L6/3600)*(1+$M6)} -> 0 | FD6: {=(IF($H6=$M$4,N$4*$I6,N$3*$I6)+(INDEX(_xlfn._xlws.FILTER('Service Duration by unit'!$D$1:$D$400,('Service Duration by unit'!$A$1:$A$400=$J6)*('Service Duration by unit'!$C$1:$C$400=_xlfn.MINIFS('Service Duration by unit'!$C$1:$C$400,'Service Duration by unit'!$A$1:$A$400,$J6,'Service Duration by unit'!$C$1:$C$400,">="&IF($H6=$M$4,N$4,N$3)))),1))*$L6/3600)*(1+$M6)} -> 0 | FE6: {=(IF($H6=$M$4,N$4*$I6,N$3*$I6)+(INDEX(_xlfn._xlws.FILTER('Service Duration by unit'!$D$1:$D$400,('Service Duration by unit'!$A$1:$A$400=$J6)*('Service Duration by unit'!$C$1:$C$400=_xlfn.MINIFS('Service Duration by unit'!$C$1:$C$400,'Service Duration by unit'!$A$1:$A$400,$J6,'Service Duration by unit'!$C$1:$C$400,">="&IF($H6=$M$4,N$4,N$3)))),1))*$L6/3600)*(1+$M6)} -> 0 | FF6: {=(IF($H6=$M$4,N$4*$I6,N$3*$I6)+(INDEX(_xlfn._xlws.FILTER('Service Duration by unit'!$D$1:$D$400,('Service Duration by unit'!$A$1:$A$400=$J6)*('Service Duration by unit'!$C$1:$C$400=_xlfn.MINIFS('Service Duration by unit'!$C$1:$C$400,'Service Duration by unit'!$A$1:$A$400,$J6,'Service Duration by unit'!$C$1:$C$400,">="&IF($H6=$M$4,N$4,N$3)))),1))*$L6/3600)*(1+$M6)} -> 0
