Workbook

Sheet Total Price List (v2)
A5: Name
A6: "COLORBOX" BAKLIJST GROEN DONKERGRIJS 40X33
A7: "Altis" Baklijst Eik Fineer 38X25
A8: "Anilin" Ramin Donkerblauw 14/13
A9: "Aniline" Ramin Antraciet 14/13
A10: "Aniline" Ramin Antraciet 23/13
A11: "Aniline" Ramin Donkerblauw 23/13
A12: "Aniline" Ramin Donkergroen 14/13
A13: "Aniline" Ramin Donkergroen 23/13
A14: "Aniline" Ramin Donkerrood 14/13
A15: "Aniline" Ramin Donkerrood 23/13
A16: "Aniline" Ramin Groen/Blauw 14/13
... A419: 051-156
A420: 100367
A421: 100467
A422: 1018
A423: 10190
A424: 10192
A425: 10195
A426: 105467 Altis Eik fineer 20x20
A427: 1073
A428: 1081
A429: 1084
A430: 10992 Verstevigingsprofiel 10x39
A431: 11002.R8 Verstevigingsprofiel 12x42
A432: 12-004 Alpha Aluminium Zilver + spacer
A433: 12-027 Alpha Aluminium Wit + spacer
A434: 12-250 Alpha Aluminium zwart + spacer
A435: 14004
A436: 14307
A437: 14315
A438: 1596
A439: 16371.D33 zwart 15x40
A440: 16380.D34 Wit 15x40
A441: 17915
A442: 17931
A443: 17945
A444: 180-019
A445: 214-004
A446: 215-250
...

Sheet Pricelists by Sequence
A1: Pricelist Name
A2: Default
A3: Test 1.1 - 10% Margin
A4: Test 1 - 10% margin
A5: Test 2 - 20% margin
A6: Test 3 - 30% margin | B6: -30 | N6: {=(IF(RC[-5]=R4C13,RC[-1]*RC[-4],R3C13*RC[-4])+(INDEX(_xlfn._xlws.FILTER('Service Duration by unit'!R1C4:R400C4,('Service Duration by unit'!R1C1:R400C1=RC[-3])*('Service Duration by unit'!R1C3:R400C3=_xlfn.MINIFS('Service Duration by unit'!R1C3:R400C3,'Service Duration by unit'!R1C1:R400C1,RC[-3],'Service Duration by unit'!R1C3:R400C3,">="&IF(RC[-5]=R4C13,RC[-1],R3C13)))),1))*RC[-2]/3600)*(1+RC[-1])} -> 0 | O6: {=(IF(RC[-5]=R4C13,RC[-1]*RC[-4],R3C13*RC[-4])+(INDEX(_xlfn._xlws.FILTER('Service Duration by unit'!R1C4:R400C4,('Service Duration by unit'!R1C1:R400C1=RC[-3])*('Service Duration by unit'!R1C3:R400C3=_xlfn.MINIFS('Service Duration by unit'!R1C3:R400C3,'Service Duration by unit'!R1C1:R400C1,RC[-3],'Service Duration by unit'!R1C3:R400C3,">="&IF(RC[-5]=R4C13,RC[-1],R3C13)))),1))*RC[-2]/3600)*(1+RC[-1])} -> 0 | P6: {=(IF(RC[-5]=R4C13,RC[-1]*RC[-4],R3C13*RC[-4])+(INDEX(_xlfn._xlws.FILTER('Service Duration by unit'!R1C4:R400C4,('Service Duration by unit'!R1C1:R400C1=RC[-3])*('Service Duration by unit'!R1C3:R400C3=_xlfn.MINIFS('Service Duration by unit'!R1C3:R400C3,'Service Duration by unit'!R1C1:R400C1,RC[-3],'Service Duration by unit'!R1C3:R400C3,">="&IF(RC[-5]=R4C13,RC[-1],R3C13)))),1))*RC[-2]/3600)*(1+RC[-1])} -> 0 | Q6: {=(IF(RC[-5]=R4C13,RC[-1]*RC[-4],R3C13*RC[-4])+(INDEX(_xlfn._xlws.FILTER('Service Duration by unit'!R1C4:R400C4,('Service Duration by unit'!R1C1:R400C1=RC[-3])*('Service Duration by unit'!R1C3:R400C3=_xlfn.MINIFS('Service Duration by unit'!R1C3:R400C3,'Service Duration by unit'!R1C1:R400C1,RC[-3],'Service Duration by unit'!R1C3:R400C3,">="&IF(RC[-5]=R4C13,RC[-1],R3C13)))),1))*RC[-2]/3600)*(1+RC[-1])} -> 0 | R6: {=(IF(RC[-5]=R4C13,RC[-1]*RC[-4],R3C13*RC[-4])+(INDEX(_xlfn._xlws.FILTER('Service Duration by unit'!R1C4:R400C4,('Service Duration by unit'!R1C1:R400C1=RC[-3])*('Service Duration by unit'!R1C3:R400C3=_xlfn.MINIFS('Service Duration by unit'!R1C3:R400C3,'Service Duration by unit'!R1C1:R400C1,RC[-3],'Service Duration by unit'!R1C3:R400C3,">="&IF(RC[-5]=R4C13,RC[-1],R3C13)))),1))*RC[-2]/3600)*(1+RC[-1])} -> 0 | S6: {=(IF(RC[-5]=R4C13,RC[-1]*RC[-4],R3C13*RC[-4])+(INDEX(_xlfn._xlws.FILTER('Service Duration by unit'!R1C4:R400C4,('Service Duration by unit'!R1C1:R400C1=RC[-3])*('Service Duration by unit'!R1C3:R400C3=_xlfn.MINIFS('Service Duration by unit'!R1C3:R400C3,'Service Duration by unit'!R1C1:R400C1,RC[-3],'Service Duration by unit'!R1C3:R400C3,">="&IF(RC[-5]=R4C13,RC[-1],R3C13)))),1))*RC[-2]/3600)*(1+RC[-1])} -> 0 | T6: {=(IF(RC[-5]=R4C13,RC[-1]*RC[-4],R3C13*RC[-4])+(INDEX(_xlfn._xlws.FILTER('Service Duration by unit'!R1C4:R400C4,('Service Duration by unit'!R1C1:R400C1=RC[-3])*('Service Duration by unit'!R1C3:R400C3=_xlfn.MINIFS('Service Duration by unit'!R1C3:R400C3,'Service Duration by unit'!R1C1:R400C1,RC[-3],'Service Duration by unit'!R1C3:R400C3,">="&IF(RC[-5]=R4C13,RC[-1],R3C13)))),1))*RC[-2]/3600)*(1+RC[-1])} -> 0 | U6: {=(IF(RC[-5]=R4C13,RC[-1]*RC[-4],R3C13*RC[-4])+(INDEX(_xlfn._xlws.FILTER('Service Duration by unit'!R1C4:R400C4,('Service Duration by unit'!R1C1:R400C1=RC[-3])*('Service Duration by unit'!R1C3:R400C3=_xlfn.MINIFS('Service Duration by unit'!R1C3:R400C3,'Service Duration by unit'!R1C1:R400C1,RC[-3],'Service Duration by unit'!R1C3:R400C3,">="&IF(RC[-5]=R4C13,RC[-1],R3C13)))),1))*RC[-2]/3600)*(1+RC[-1])} -> 0 | ... FF6: {=(IF(RC[-5]=R4C13,RC[-1]*RC[-4],R3C13*RC[-4])+(INDEX(_xlfn._xlws.FILTER('Service Duration by unit'!R1C4:R400C4,('Service Duration by unit'!R1C1:R400C1=RC[-3])*('Service Duration by unit'!R1C3:R400C3=_xlfn.MINIFS('Service Duration by unit'!R1C3:R400C3,'Service Duration by unit'!R1C1:R400C1,RC[-3],'Service Duration by unit'!R1C3:R400C3,">="&IF(RC[-5]=R4C13,RC[-1],R3C13)))),1))*RC[-2]/3600)*(1+RC[-1])} -> 0
N7: {=(IF(RC[-5]=R4C13,RC[-1]*RC[-4],R3C13*RC[-4])+(INDEX(_xlfn._xlws.FILTER('Service Duration by unit'!R1C4:R400C4,('Service Duration by unit'!R1C1:R400C1=RC[-3])*('Service Duration by unit'!R1C3:R400C3=_xlfn.MINIFS('Service Duration by unit'!R1C3:R400C3,'Service Duration by unit'!R1C1:R400C1,RC[-3],'Service Duration by unit'!R1C3:R400C3,">="&IF(RC[-5]=R4C13,RC[-1],R3C13)))),1))*RC[-2]/3600)*(1+RC[-1])} -> 0 | O7: {=(IF(RC[-5]=R4C13,RC[-1]*RC[-4],R3C13*RC[-4])+(INDEX(_xlfn._xlws.FILTER('Service Duration by unit'!R1C4:R400C4,('Service Duration by unit'!R1C1:R400C1=RC[-3])*('Service Duration by unit'!R1C3:R400C3=_xlfn.MINIFS('Service Duration by unit'!R1C3:R400C3,'Service Duration by unit'!R1C1:R400C1,RC[-3],'Service Duration by unit'!R1C3:R400C3,">="&IF(RC[-5]=R4C13,RC[-1],R3C13)))),1))*RC[-2]/3600)*(1+RC[-1])} -> 0 | P7: {=(IF(RC[-5]=R4C13,RC[-1]*RC[-4],R3C13*RC[-4])+(INDEX(_xlfn._xlws.FILTER('Service Duration by unit'!R1C4:R400C4,('Service Duration by unit'!R1C1:R400C1=RC[-3])*('Service Duration by unit'!R1C3:R400C3=_xlfn.MINIFS('Service Duration by unit'!R1C3:R400C3,'Service Duration by unit'!R1C1:R400C1,RC[-3],'Service Duration by unit'!R1C3:R400C3,">="&IF(RC[-5]=R4C13,RC[-1],R3C13)))),1))*RC[-2]/3600)*(1+RC[-1])} -> 0 | Q7: {=(IF(RC[-5]=R4C13,RC[-1]*RC[-4],R3C13*RC[-4])+(INDEX(_xlfn._xlws.FILTER('Service Duration by unit'!R1C4:R400C4,('Service Duration by unit'!R1C1:R400C1=RC[-3])*('Service Duration by unit'!R1C3:R400C3=_xlfn.MINIFS('Service Duration by unit'!R1C3:R400C3,'Service Duration by unit'!R1C1:R400C1,RC[-3],'Service Duration by unit'!R1C3:R400C3,">="&IF(RC[-5]=R4C13,RC[-1],R3C13)))),1))*RC[-2]/3600)*(1+RC[-1])} -> 0 | R7: {=(IF(RC[-5]=R4C13,RC[-1]*RC[-4],R3C13*RC[-4])+(INDEX(_xlfn._xlws.FILTER('Service Duration by unit'!R1C4:R400C4,('Service Duration by unit'!R1C1:R400C1=RC[-3])*('Service Duration by unit'!R1C3:R400C3=_xlfn.MINIFS('Service Duration by unit'!R1C3:R400C3,'Service Duration by unit'!R1C1:R400C1,RC[-3],'Service Duration by unit'!R1C3:R400C3,">="&IF(RC[-5]=R4C13,RC[-1],R3C13)))),1))*RC[-2]/3600)*(1+RC[-1])} -> 0 | S7: {=(IF(RC[-5]=R4C13,RC[-1]*RC[-4],R3C13*RC[-4])+(INDEX(_xlfn._xlws.FILTER('Service Duration by unit'!R1C4:R400C4,('Service Duration by unit'!R1C1:R400C1=RC[-3])*('Service Duration by unit'!R1C3:R400C3=_xlfn.MINIFS('Service Duration by unit'!R1C3:R400C3,'Service Duration by unit'!R1C1:R400C1,RC[-3],'Service Duration by unit'!R1C3:R400C3,">="&IF(RC[-5]=R4C13,RC[-1],R3C13)))),1))*RC[-2]/3600)*(1+RC[-1])} -> 0 | T7: {=(IF(RC[-5]=R4C13,RC[-1]*RC[-4],R3C13*RC[-4])+(INDEX(_xlfn._xlws.FILTER('Service Duration by unit'!R1C4:R400C4,('Service Duration by unit'!R1C1:R400C1=RC[-3])*('Service Duration by unit'!R1C3:R400C3=_xlfn.MINIFS('Service Duration by unit'!R1C3:R400C3,'Service Duration by unit'!R1C1:R400C1,RC[-3],'Service Duration by unit'!R1C3:R400C3,">="&IF(RC[-5]=R4C13,RC[-1],R3C13)))),1))*RC[-2]/3600)*(1+RC[-1])} -> 0 | U7: {=(IF(RC[-5]=R4C13,RC[-1]*RC[-4],R3C13*RC[-4])+(INDEX(_xlfn._xlws.FILTER('Service Duration by unit'!R1C4:R400C4,('Service Duration by unit'!R1C1:R400C1=RC[-3])*('Service Duration by unit'!R1C3:R400C3=_xlfn.MINIFS('Service Duration by unit'!R1C3:R400C3,'Service Duration by unit'!R1C1:R400C1,RC[-3],'Service Duration by unit'!R1C3:R400C3,">="&IF(RC[-5]=R4C13,RC[-1],R3C13)))),1))*RC[-2]/3600)*(1+RC[-1])} -> 0 | ... FF7: {=(IF(RC[-5]=R4C13,RC[-1]*RC[-4],R3C13*RC[-4])+(INDEX(_xlfn._xlws.FILTER('Service Duration by unit'!R1C4:R400C4,('Service Duration by unit'!R1C1:R400C1=RC[-3])*('Service Duration by unit'!R1C3:R400C3=_xlfn.MINIFS('Service Duration by unit'!R1C3:R400C3,'Service Duration by unit'!R1C1:R400C1,RC[-3],'Service Duration by unit'!R1C3:R400C3,">="&IF(RC[-5]=R4C13,RC[-1],R3C13)))),1))*RC[-2]/3600)*(1+RC[-1])} -> 0
N8: {=(IF(RC[-5]=R4C13,RC[-1]*RC[-4],R3C13*RC[-4])+(INDEX(_xlfn._xlws.FILTER('Service Duration by unit'!R1C4:R400C4,('Service Duration by unit'!R1C1:R400C1=RC[-3])*('Service Duration by unit'!R1C3:R400C3=_xlfn.MINIFS('Service Duration by unit'!R1C3:R400C3,'Service Duration by unit'!R1C1:R400C1,RC[-3],'Service Duration by unit'!R1C3:R400C3,">="&IF(RC[-5]=R4C13,RC[-1],R3C13)))),1))*RC[-2]/3600)*(1+RC[-1])} -> 0 | O8: {=(IF(RC[-5]=R4C13,RC[-1]*RC[-4],R3C13*RC[-4])+(INDEX(_xlfn._xlws.FILTER('Service Duration by unit'!R1C4:R400C4,('Service Duration by unit'!R1C1:R400C1=RC[-3])*('Service Duration by unit'!R1C3:R400C3=_xlfn.MINIFS('Service Duration by unit'!R1C3:R400C3,'Service Duration by unit'!R1C1:R400C1,RC[-3],'Service Duration by unit'!R1C3:R400C3,">="&IF(RC[-5]=R4C13,RC[-1],R3C13)))),1))*RC[-2]/3600)*(1+RC[-1])} -> 0 | P8: {=(IF(RC[-5]=R4C13,RC[-1]*RC[-4],R3C13*RC[-4])+(INDEX(_xlfn._xlws.FILTER('Service Duration by unit'!R1C4:R400C4,('Service Duration by unit'!R1C1:R400C1=RC[-3])*('Service Duration by unit'!R1C3:R400C3=_xlfn.MINIFS('Service Duration by unit'!R1C3:R400C3,'Service Duration by unit'!R1C1:R400C1,RC[-3],'Service Duration by unit'!R1C3:R400C3,">="&IF(RC[-5]=R4C13,RC[-1],R3C13)))),1))*RC[-2]/3600)*(1+RC[-1])} -> 0 | Q8: {=(IF(RC[-5]=R4C13,RC[-1]*RC[-4],R3C13*RC[-4])+(INDEX(_xlfn._xlws.FILTER('Service Duration by unit'!R1C4:R400C4,('Service Duration by unit'!R1C1:R400C1=RC[-3])*('Service Duration by unit'!R1C3:R400C3=_xlfn.MINIFS('Service Duration by unit'!R1C3:R400C3,'Service Duration by unit'!R1C1:R400C1,RC[-3],'Service Duration by unit'!R1C3:R400C3,">="&IF(RC[-5]=R4C13,RC[-1],R3C13)))),1))*RC[-2]/3600)*(1+RC[-1])} -> 0 | R8: {=(IF(RC[-5]=R4C13,RC[-1]*RC[-4],R3C13*RC[-4])+(INDEX(_xlfn._xlws.FILTER('Service Duration by unit'!R1C4:R400C4,('Service Duration by unit'!R1C1:R400C1=RC[-3])*('Service Duration by unit'!R1C3:R400C3=_xlfn.MINIFS('Service Duration by unit'!R1C3:R400C3,'Service Duration by unit'!R1C1:R400C1,RC[-3],'Service Duration by unit'!R1C3:R400C3,">="&IF(RC[-5]=R4C13,RC[-1],R3C13)))),1))*RC[-2]/3600)*(1+RC[-1])} -> 0 | S8: {=(IF(RC[-5]=R4C13,RC[-1]*RC[-4],R3C13*RC[-4])+(INDEX(_xlfn._xlws.FILTER('Service Duration by unit'!R1C4:R400C4,('Service Duration by unit'!R1C1:R400C1=RC[-3])*('Service Duration by unit'!R1C3:R400C3=_xlfn.MINIFS('Service Duration by unit'!R1C3:R400C3,'Service Duration by unit'!R1C1:R400C1,RC[-3],'Service Duration by unit'!R1C3:R400C3,">="&IF(RC[-5]=R4C13,RC[-1],R3C13)))),1))*RC[-2]/3600)*(1+RC[-1])} -> 0 | T8: {=(IF(RC[-5]=R4C13,RC[-1]*RC[-4],R3C13*RC[-4])+(INDEX(_xlfn._xlws.FILTER('Service Duration by unit'!R1C4:R400C4,('Service Duration by unit'!R1C1:R400C1=RC[-3])*('Service Duration by unit'!R1C3:R400C3=_xlfn.MINIFS('Service Duration by unit'!R1C3:R400C3,'Service Duration by unit'!R1C1:R400C1,RC[-3],'Service Duration by unit'!R1C3:R400C3,">="&IF(RC[-5]=R4C13,RC[-1],R3C13)))),1))*RC[-2]/3600)*(1+RC[-1])} -> 0 | U8: {=(IF(RC[-5]=R4C13,RC[-1]*RC[-4],R3C13*RC[-4])+(INDEX(_xlfn._xlws.FILTER('Service Duration by unit'!R1C4:R400C4,('Service Duration by unit'!R1C1:R400C1=RC[-3])*('Service Duration by unit'!R1C3:R400C3=_xlfn.MINIFS('Service Duration by unit'!R1C3:R400C3,'Service Duration by unit'!R1C1:R400C1,RC[-3],'Service Duration by unit'!R1C3:R400C3,">="&IF(RC[-5]=R4C13,RC[-1],R3C13)))),1))*RC[-2]/3600)*(1+RC[-1])} -> 0 | ... FF8: {=(IF(RC[-5]=R4C13,RC[-1]*RC[-4],R3C13*RC[-4])+(INDEX(_xlfn._xlws.FILTER('Service Duration by unit'!R1C4:R400C4,('Service Duration by unit'!R1C1:R400C1=RC[-3])*('Service Duration by unit'!R1C3:R400C3=_xlfn.MINIFS('Service Duration by unit'!R1C3:R400C3,'Service Duration by unit'!R1C1:R400C1,RC[-3],'Service Duration by unit'!R1C3:R400C3,">="&IF(RC[-5]=R4C13,RC[-1],R3C13)))),1))*RC[-2]/3600)*(1+RC[-1])} -> 0
N9: {=(IF(RC[-5]=R4C13,RC[-1]*RC[-4],R3C13*RC[-4])+(INDEX(_xlfn._xlws.FILTER('Service Duration by unit'!R1C4:R400C4,('Service Duration by unit'!R1C1:R400C1=RC[-3])*('Service Duration by unit'!R1C3:R400C3=_xlfn.MINIFS('Service Duration by unit'!R1C3:R400C3,'Service Duration by unit'!R1C1:R400C1,RC[-3],'Service Duration by unit'!R1C3:R400C3,">="&IF(RC[-5]=R4C13,RC[-1],R3C13)))),1))*RC[-2]/3600)*(1+RC[-1])} -> 0 | O9: {=(IF(RC[-5]=R4C13,RC[-1]*RC[-4],R3C13*RC[-4])+(INDEX(_xlfn._xlws.FILTER('Service Duration by unit'!R1C4:R400C4,('Service Duration by unit'!R1C1:R400C1=RC[-3])*('Service Duration by unit'!R1C3:R400C3=_xlfn.MINIFS('Service Duration by unit'!R1C3:R400C3,'Service Duration by unit'!R1C1:R400C1,RC[-3],'Service Duration by unit'!R1C3:R400C3,">="&IF(RC[-5]=R4C13,RC[-1],R3C13)))),1))*RC[-2]/3600)*(1+RC[-1])} -> 0 | P9: {=(IF(RC[-5]=R4C13,RC[-1]*RC[-4],R3C13*RC[-4])+(INDEX(_xlfn._xlws.FILTER('Service Duration by unit'!R1C4:R400C4,('Service Duration by unit'!R1C1:R400C1=RC[-3])*('Service Duration by unit'!R1C3:R400C3=_xlfn.MINIFS('Service Duration by unit'!R1C3:R400C3,'Service Duration by unit'!R1C1:R400C1,RC[-3],'Service Duration by unit'!R1C3:R400C3,">="&IF(RC[-5]=R4C13,RC[-1],R3C13)))),1))*RC[-2]/3600)*(1+RC[-1])} -> 0 | Q9: {=(IF(RC[-5]=R4C13,RC[-1]*RC[-4],R3C13*RC[-4])+(INDEX(_xlfn._xlws.FILTER('Service Duration by unit'!R1C4:R400C4,('Service Duration by unit'!R1C1:R400C1=RC[-3])*('Service Duration by unit'!R1C3:R400C3=_xlfn.MINIFS('Service Duration by unit'!R1C3:R400C3,'Service Duration by unit'!R1C1:R400C1,RC[-3],'Service Duration by unit'!R1C3:R400C3,">="&IF(RC[-5]=R4C13,RC[-1],R3C13)))),1))*RC[-2]/3600)*(1+RC[-1])} -> 0 | R9: {=(IF(RC[-5]=R4C13,RC[-1]*RC[-4],R3C13*RC[-4])+(INDEX(_xlfn._xlws.FILTER('Service Duration by unit'!R1C4:R400C4,('Service Duration by unit'!R1C1:R400C1=RC[-3])*('Service Duration by unit'!R1C3:R400C3=_xlfn.MINIFS('Service Duration by unit'!R1C3:R400C3,'Service Duration by unit'!R1C1:R400C1,RC[-3],'Service Duration by unit'!R1C3:R400C3,">="&IF(RC[-5]=R4C13,RC[-1],R3C13)))),1))*RC[-2]/3600)*(1+RC[-1])} -> 0 | S9: {=(IF(RC[-5]=R4C13,RC[-1]*RC[-4],R3C13*RC[-4])+(INDEX(_xlfn._xlws.FILTER('Service Duration by unit'!R1C4:R400C4,('Service Duration by unit'!R1C1:R400C1=RC[-3])*('Service Duration by unit'!R1C3:R400C3=_xlfn.MINIFS('Service Duration by unit'!R1C3:R400C3,'Service Duration by unit'!R1C1:R400C1,RC[-3],'Service Duration by unit'!R1C3:R400C3,">="&IF(RC[-5]=R4C13,RC[-1],R3C13)))),1))*RC[-2]/3600)*(1+RC[-1])} -> 0 | T9: {=(IF(RC[-5]=R4C13,RC[-1]*RC[-4],R3C13*RC[-4])+(INDEX(_xlfn._xlws.FILTER('Service Duration by unit'!R1C4:R400C4,('Service Duration by unit'!R1C1:R400C1=RC[-3])*('Service Duration by unit'!R1C3:R400C3=_xlfn.MINIFS('Service Duration by unit'!R1C3:R400C3,'Service Duration by unit'!R1C1:R400C1,RC[-3],'Service Duration by unit'!R1C3:R400C3,">="&IF(RC[-5]=R4C13,RC[-1],R3C13)))),1))*RC[-2]/3600)*(1+RC[-1])} -> 0 | U9: {=(IF(RC[-5]=R4C13,RC[-1]*RC[-4],R3C13*RC[-4])+(INDEX(_xlfn._xlws.FILTER('Service Duration by unit'!R1C4:R400C4,('Service Duration by unit'!R1C1:R400C1=RC[-3])*('Service Duration by unit'!R1C3:R400C3=_xlfn.MINIFS('Service Duration by unit'!R1C3:R400C3,'Service Duration by unit'!R1C1:R400C1,RC[-3],'Service Duration by unit'!R1C3:R400C3,">="&IF(RC[-5]=R4C13,RC[-1],R3C13)))),1))*RC[-2]/3600)*(1+RC[-1])} -> 0 | ... FF9: {=(IF(RC[-5]=R4C13,RC[-1]*RC[-4],R3C13*RC[-4])+(INDEX(_xlfn._xlws.FILTER('Service Duration by unit'!R1C4:R400C4,('Service Duration by unit'!R1C1:R400C1=RC[-3])*('Service Duration by unit'!R1C3:R400C3=_xlfn.MINIFS('Service Duration by unit'!R1C3:R400C3,'Service Duration by unit'!R1C1:R400C1,RC[-3],'Service Duration by unit'!R1C3:R400C3,">="&IF(RC[-5]=R4C13,RC[-1],R3C13)))),1))*RC[-2]/3600)*(1+RC[-1])} -> 0
N10: {=(IF(RC[-5]=R4C13,RC[-1]*RC[-4],R3C13*RC[-4])+(INDEX(_xlfn._xlws.FILTER('Service Duration by unit'!R1C4:R400C4,('Service Duration by unit'!R1C1:R400C1=RC[-3])*('Service Duration by unit'!R1C3:R400C3=_xlfn.MINIFS('Service Duration by unit'!R1C3:R400C3,'Service Duration by unit'!R1C1:R400C1,RC[-3],'Service Duration by unit'!R1C3:R400C3,">="&IF(RC[-5]=R4C13,RC[-1],R3C13)))),1))*RC[-2]/3600)*(1+RC[-1])} -> 0 | O10: {=(IF(RC[-5]=R4C13,RC[-1]*RC[-4],R3C13*RC[-4])+(INDEX(_xlfn._xlws.FILTER('Service Duration by unit'!R1C4:R400C4,('Service Duration by unit'!R1C1:R400C1=RC[-3])*('Service Duration by unit'!R1C3:R400C3=_xlfn.MINIFS('Service Duration by unit'!R1C3:R400C3,'Service Duration by unit'!R1C1:R400C1,RC[-3],'Service Duration by unit'!R1C3:R400C3,">="&IF(RC[-5]=R4C13,RC[-1],R3C13)))),1))*RC[-2]/3600)*(1+RC[-1])} -> 0 | P10: {=(IF(RC[-5]=R4C13,RC[-1]*RC[-4],R3C13*RC[-4])+(INDEX(_xlfn._xlws.FILTER('Service Duration by unit'!R1C4:R400C4,('Service Duration by unit'!R1C1:R400C1=RC[-3])*('Service Duration by unit'!R1C3:R400C3=_xlfn.MINIFS('Service Duration by unit'!R1C3:R400C3,'Service Duration by unit'!R1C1:R400C1,RC[-3],'Service Duration by unit'!R1C3:R400C3,">="&IF(RC[-5]=R4C13,RC[-1],R3C13)))),1))*RC[-2]/3600)*(1+RC[-1])} -> 0 | Q10: {=(IF(RC[-5]=R4C13,RC[-1]*RC[-4],R3C13*RC[-4])+(INDEX(_xlfn._xlws.FILTER('Service Duration by unit'!R1C4:R400C4,('Service Duration by unit'!R1C1:R400C1=RC[-3])*('Service Duration by unit'!R1C3:R400C3=_xlfn.MINIFS('Service Duration by unit'!R1C3:R400C3,'Service Duration by unit'!R1C1:R400C1,RC[-3],'Service Duration by unit'!R1C3:R400C3,">="&IF(RC[-5]=R4C13,RC[-1],R3C13)))),1))*RC[-2]/3600)*(1+RC[-1])} -> 0 | R10: {=(IF(RC[-5]=R4C13,RC[-1]*RC[-4],R3C13*RC[-4])+(INDEX(_xlfn._xlws.FILTER('Service Duration by unit'!R1C4:R400C4,('Service Duration by unit'!R1C1:R400C1=RC[-3])*('Service Duration by unit'!R1C3:R400C3=_xlfn.MINIFS('Service Duration by unit'!R1C3:R400C3,'Service Duration by unit'!R1C1:R400C1,RC[-3],'Service Duration by unit'!R1C3:R400C3,">="&IF(RC[-5]=R4C13,RC[-1],R3C13)))),1))*RC[-2]/3600)*(1+RC[-1])} -> 0 | S10: {=(IF(RC[-5]=R4C13,RC[-1]*RC[-4],R3C13*RC[-4])+(INDEX(_xlfn._xlws.FILTER('Service Duration by unit'!R1C4:R400C4,('Service Duration by unit'!R1C1:R400C1=RC[-3])*('Service Duration by unit'!R1C3:R400C3=_xlfn.MINIFS('Service Duration by unit'!R1C3:R400C3,'Service Duration by unit'!R1C1:R400C1,RC[-3],'Service Duration by unit'!R1C3:R400C3,">="&IF(RC[-5]=R4C13,RC[-1],R3C13)))),1))*RC[-2]/3600)*(1+RC[-1])} -> 0 | T10: {=(IF(RC[-5]=R4C13,RC[-1]*RC[-4],R3C13*RC[-4])+(INDEX(_xlfn._xlws.FILTER('Service Duration by unit'!R1C4:R400C4,('Service Duration by unit'!R1C1:R400C1=RC[-3])*('Service Duration by unit'!R1C3:R400C3=_xlfn.MINIFS('Service Duration by unit'!R1C3:R400C3,'Service Duration by unit'!R1C1:R400C1,RC[-3],'Service Duration by unit'!R1C3:R400C3,">="&IF(RC[-5]=R4C13,RC[-1],R3C13)))),1))*RC[-2]/3600)*(1+RC[-1])} -> 0 | U10: {=(IF(RC[-5]=R4C13,RC[-1]*RC[-4],R3C13*RC[-4])+(INDEX(_xlfn._xlws.FILTER('Service Duration by unit'!R1C4:R400C4,('Service Duration by unit'!R1C1:R400C1=RC[-3])*('Service Duration by unit'!R1C3:R400C3=_xlfn.MINIFS('Service Duration by unit'!R1C3:R400C3,'Service Duration by unit'!R1C1:R400C1,RC[-3],'Service Duration by unit'!R1C3:R400C3,">="&IF(RC[-5]=R4C13,RC[-1],R3C13)))),1))*RC[-2]/3600)*(1+RC[-1])} -> 0 | ... FF10: {=(IF(RC[-5]=R4C13,RC[-1]*RC[-4],R3C13*RC[-4])+(INDEX(_xlfn._xlws.FILTER('Service Duration by unit'!R1C4:R400C4,('Service Duration by unit'!R1C1:R400C1=RC[-3])*('Service Duration by unit'!R1C3:R400C3=_xlfn.MINIFS('Service Duration by unit'!R1C3:R400C3,'Service Duration by unit'!R1C1:R400C1,RC[-3],'Service Duration by unit'!R1C3:R400C3,">="&IF(RC[-5]=R4C13,RC[-1],R3C13)))),1))*RC[-2]/3600)*(1+RC[-1])} -> 0
N11: {=(IF(RC[-5]=R4C13,RC[-1]*RC[-4],R3C13*RC[-4])+(INDEX(_xlfn._xlws.FILTER('Service Duration by unit'!R1C4:R400C4,('Service Duration by unit'!R1C1:R400C1=RC[-3])*('Service Duration by unit'!R1C3:R400C3=_xlfn.MINIFS('Service Duration by unit'!R1C3:R400C3,'Service Duration by unit'!R1C1:R400C1,RC[-3],'Service Duration by unit'!R1C3:R400C3,">="&IF(RC[-5]=R4C13,RC[-1],R3C13)))),1))*RC[-2]/3600)*(1+RC[-1])} -> 0 | O11: {=(IF(RC[-5]=R4C13,RC[-1]*RC[-4],R3C13*RC[-4])+(INDEX(_xlfn._xlws.FILTER('Service Duration by unit'!R1C4:R400C4,('Service Duration by unit'!R1C1:R400C1=RC[-3])*('Service Duration by unit'!R1C3:R400C3=_xlfn.MINIFS('Service Duration by unit'!R1C3:R400C3,'Service Duration by unit'!R1C1:R400C1,RC[-3],'Service Duration by unit'!R1C3:R400C3,">="&IF(RC[-5]=R4C13,RC[-1],R3C13)))),1))*RC[-2]/3600)*(1+RC[-1])} -> 0 | P11: {=(IF(RC[-5]=R4C13,RC[-1]*RC[-4],R3C13*RC[-4])+(INDEX(_xlfn._xlws.FILTER('Service Duration by unit'!R1C4:R400C4,('Service Duration by unit'!R1C1:R400C1=RC[-3])*('Service Duration by unit'!R1C3:R400C3=_xlfn.MINIFS('Service Duration by unit'!R1C3:R400C3,'Service Duration by unit'!R1C1:R400C1,RC[-3],'Service Duration by unit'!R1C3:R400C3,">="&IF(RC[-5]=R4C13,RC[-1],R3C13)))),1))*RC[-2]/3600)*(1+RC[-1])} -> 0 | Q11: {=(IF(RC[-5]=R4C13,RC[-1]*RC[-4],R3C13*RC[-4])+(INDEX(_xlfn._xlws.FILTER('Service Duration by unit'!R1C4:R400C4,('Service Duration by unit'!R1C1:R400C1=RC[-3])*('Service Duration by unit'!R1C3:R400C3=_xlfn.MINIFS('Service Duration by unit'!R1C3:R400C3,'Service Duration by unit'!R1C1:R400C1,RC[-3],'Service Duration by unit'!R1C3:R400C3,">="&IF(RC[-5]=R4C13,RC[-1],R3C13)))),1))*RC[-2]/3600)*(1+RC[-1])} -> 0 | R11: {=(IF(RC[-5]=R4C13,RC[-1]*RC[-4],R3C13*RC[-4])+(INDEX(_xlfn._xlws.FILTER('Service Duration by unit'!R1C4:R400C4,('Service Duration by unit'!R1C1:R400C1=RC[-3])*('Service Duration by unit'!R1C3:R400C3=_xlfn.MINIFS('Service Duration by unit'!R1C3:R400C3,'Service Duration by unit'!R1C1:R400C1,RC[-3],'Service Duration by unit'!R1C3:R400C3,">="&IF(RC[-5]=R4C13,RC[-1],R3C13)))),1))*RC[-2]/3600)*(1+RC[-1])} -> 0 | S11: {=(IF(RC[-5]=R4C13,RC[-1]*RC[-4],R3C13*RC[-4])+(INDEX(_xlfn._xlws.FILTER('Service Duration by unit'!R1C4:R400C4,('Service Duration by unit'!R1C1:R400C1=RC[-3])*('Service Duration by unit'!R1C3:R400C3=_xlfn.MINIFS('Service Duration by unit'!R1C3:R400C3,'Service Duration by unit'!R1C1:R400C1,RC[-3],'Service Duration by unit'!R1C3:R400C3,">="&IF(RC[-5]=R4C13,RC[-1],R3C13)))),1))*RC[-2]/3600)*(1+RC[-1])} -> 0 | T11: {=(IF(RC[-5]=R4C13,RC[-1]*RC[-4],R3C13*RC[-4])+(INDEX(_xlfn._xlws.FILTER('Service Duration by unit'!R1C4:R400C4,('Service Duration by unit'!R1C1:R400C1=RC[-3])*('Service Duration by unit'!R1C3:R400C3=_xlfn.MINIFS('Service Duration by unit'!R1C3:R400C3,'Service Duration by unit'!R1C1:R400C1,RC[-3],'Service Duration by unit'!R1C3:R400C3,">="&IF(RC[-5]=R4C13,RC[-1],R3C13)))),1))*RC[-2]/3600)*(1+RC[-1])} -> 0 | U11: {=(IF(RC[-5]=R4C13,RC[-1]*RC[-4],R3C13*RC[-4])+(INDEX(_xlfn._xlws.FILTER('Service Duration by unit'!R1C4:R400C4,('Service Duration by unit'!R1C1:R400C1=RC[-3])*('Service Duration by unit'!R1C3:R400C3=_xlfn.MINIFS('Service Duration by unit'!R1C3:R400C3,'Service Duration by unit'!R1C1:R400C1,RC[-3],'Service Duration by unit'!R1C3:R400C3,">="&IF(RC[-5]=R4C13,RC[-1],R3C13)))),1))*RC[-2]/3600)*(1+RC[-1])} -> 0 | ... FF11: {=(IF(RC[-5]=R4C13,RC[-1]*RC[-4],R3C13*RC[-4])+(INDEX(_xlfn._xlws.FILTER('Service Duration by unit'!R1C4:R400C4,('Service Duration by unit'!R1C1:R400C1=RC[-3])*('Service Duration by unit'!R1C3:R400C3=_xlfn.MINIFS('Service Duration by unit'!R1C3:R400C3,'Service Duration by unit'!R1C1:R400C1,RC[-3],'Service Duration by unit'!R1C3:R400C3,">="&IF(RC[-5]=R4C13,RC[-1],R3C13)))),1))*RC[-2]/3600)*(1+RC[-1])} -> 0
N12: {=(IF(RC[-5]=R4C13,RC[-1]*RC[-4],R3C13*RC[-4])+(INDEX(_xlfn._xlws.FILTER('Service Duration by unit'!R1C4:R400C4,('Service Duration by unit'!R1C1:R400C1=RC[-3])*('Service Duration by unit'!R1C3:R400C3=_xlfn.MINIFS('Service Duration by unit'!R1C3:R400C3,'Service Duration by unit'!R1C1:R400C1,RC[-3],'Service Duration by unit'!R1C3:R400C3,">="&IF(RC[-5]=R4C13,RC[-1],R3C13)))),1))*RC[-2]/3600)*(1+RC[-1])} -> 0 | O12: {=(IF(RC[-5]=R4C13,RC[-1]*RC[-4],R3C13*RC[-4])+(INDEX(_xlfn._xlws.FILTER('Service Duration by unit'!R1C4:R400C4,('Service Duration by unit'!R1C1:R400C1=RC[-3])*('Service Duration by unit'!R1C3:R400C3=_xlfn.MINIFS('Service Duration by unit'!R1C3:R400C3,'Service Duration by unit'!R1C1:R400C1,RC[-3],'Service Duration by unit'!R1C3:R400C3,">="&IF(RC[-5]=R4C13,RC[-1],R3C13)))),1))*RC[-2]/3600)*(1+RC[-1])} -> 0 | P12: {=(IF(RC[-5]=R4C13,RC[-1]*RC[-4],R3C13*RC[-4])+(INDEX(_xlfn._xlws.FILTER('Service Duration by unit'!R1C4:R400C4,('Service Duration by unit'!R1C1:R400C1=RC[-3])*('Service Duration by unit'!R1C3:R400C3=_xlfn.MINIFS('Service Duration by unit'!R1C3:R400C3,'Service Duration by unit'!R1C1:R400C1,RC[-3],'Service Duration by unit'!R1C3:R400C3,">="&IF(RC[-5]=R4C13,RC[-1],R3C13)))),1))*RC[-2]/3600)*(1+RC[-1])} -> 0 | Q12: {=(IF(RC[-5]=R4C13,RC[-1]*RC[-4],R3C13*RC[-4])+(INDEX(_xlfn._xlws.FILTER('Service Duration by unit'!R1C4:R400C4,('Service Duration by unit'!R1C1:R400C1=RC[-3])*('Service Duration by unit'!R1C3:R400C3=_xlfn.MINIFS('Service Duration by unit'!R1C3:R400C3,'Service Duration by unit'!R1C1:R400C1,RC[-3],'Service Duration by unit'!R1C3:R400C3,">="&IF(RC[-5]=R4C13,RC[-1],R3C13)))),1))*RC[-2]/3600)*(1+RC[-1])} -> 0 | R12: {=(IF(RC[-5]=R4C13,RC[-1]*RC[-4],R3C13*RC[-4])+(INDEX(_xlfn._xlws.FILTER('Service Duration by unit'!R1C4:R400C4,('Service Duration by unit'!R1C1:R400C1=RC[-3])*('Service Duration by unit'!R1C3:R400C3=_xlfn.MINIFS('Service Duration by unit'!R1C3:R400C3,'Service Duration by unit'!R1C1:R400C1,RC[-3],'Service Duration by unit'!R1C3:R400C3,">="&IF(RC[-5]=R4C13,RC[-1],R3C13)))),1))*RC[-2]/3600)*(1+RC[-1])} -> 0 | S12: {=(IF(RC[-5]=R4C13,RC[-1]*RC[-4],R3C13*RC[-4])+(INDEX(_xlfn._xlws.FILTER('Service Duration by unit'!R1C4:R400C4,('Service Duration by unit'!R1C1:R400C1=RC[-3])*('Service Duration by unit'!R1C3:R400C3=_xlfn.MINIFS('Service Duration by unit'!R1C3:R400C3,'Service Duration by unit'!R1C1:R400C1,RC[-3],'Service Duration by unit'!R1C3:R400C3,">="&IF(RC[-5]=R4C13,RC[-1],R3C13)))),1))*RC[-2]/3600)*(1+RC[-1])} -> 0 | T12: {=(IF(RC[-5]=R4C13,RC[-1]*RC[-4],R3C13*RC[-4])+(INDEX(_xlfn._xlws.FILTER('Service Duration by unit'!R1C4:R400C4,('Service Duration by unit'!R1C1:R400C1=RC[-3])*('Service Duration by unit'!R1C3:R400C3=_xlfn.MINIFS('Service Duration by unit'!R1C3:R400C3,'Service Duration by unit'!R1C1:R400C1,RC[-3],'Service Duration by unit'!R1C3:R400C3,">="&IF(RC[-5]=R4C13,RC[-1],R3C13)))),1))*RC[-2]/3600)*(1+RC[-1])} -> 0 | U12: {=(IF(RC[-5]=R4C13,RC[-1]*RC[-4],R3C13*RC[-4])+(INDEX(_xlfn._xlws.FILTER('Service Duration by unit'!R1C4:R400C4,('Service Duration by unit'!R1C1:R400C1=RC[-3])*('Service Duration by unit'!R1C3:R400C3=_xlfn.MINIFS('Service Duration by unit'!R1C3:R400C3,'Service Duration by unit'!R1C1:R400C1,RC[-3],'Service Duration by unit'!R1C3:R400C3,">="&IF(RC[-5]=R4C13,RC[-1],R3C13)))),1))*RC[-2]/3600)*(1+RC[-1])} -> 0 | ... FF12: {=(IF(RC[-5]=R4C13,RC[-1]*RC[-4],R3C13*RC[-4])+(INDEX(_xlfn._xlws.FILTER('Service Duration by unit'!R1C4:R400C4,('Service Duration by unit'!R1C1:R400C1=RC[-3])*('Service Duration by unit'!R1C3:R400C3=_xlfn.MINIFS('Service Duration by unit'!R1C3:R400C3,'Service Duration by unit'!R1C1:R400C1,RC[-3],'Service Duration by unit'!R1C3:R400C3,">="&IF(RC[-5]=R4C13,RC[-1],R3C13)))),1))*RC[-2]/3600)*(1+RC[-1])} -> 0
N13: {=(IF(RC[-5]=R4C13,RC[-1]*RC[-4],R3C13*RC[-4])+(INDEX(_xlfn._xlws.FILTER('Service Duration by unit'!R1C4:R400C4,('Service Duration by unit'!R1C1:R400C1=RC[-3])*('Service Duration by unit'!R1C3:R400C3=_xlfn.MINIFS('Service Duration by unit'!R1C3:R400C3,'Service Duration by unit'!R1C1:R400C1,RC[-3],'Service Duration by unit'!R1C3:R400C3,">="&IF(RC[-5]=R4C13,RC[-1],R3C13)))),1))*RC[-2]/3600)*(1+RC[-1])} -> 0 | O13: {=(IF(RC[-5]=R4C13,RC[-1]*RC[-4],R3C13*RC[-4])+(INDEX(_xlfn._xlws.FILTER('Service Duration by unit'!R1C4:R400C4,('Service Duration by unit'!R1C1:R400C1=RC[-3])*('Service Duration by unit'!R1C3:R400C3=_xlfn.MINIFS('Service Duration by unit'!R1C3:R400C3,'Service Duration by unit'!R1C1:R400C1,RC[-3],'Service Duration by unit'!R1C3:R400C3,">="&IF(RC[-5]=R4C13,RC[-1],R3C13)))),1))*RC[-2]/3600)*(1+RC[-1])} -> 0 | P13: {=(IF(RC[-5]=R4C13,RC[-1]*RC[-4],R3C13*RC[-4])+(INDEX(_xlfn._xlws.FILTER('Service Duration by unit'!R1C4:R400C4,('Service Duration by unit'!R1C1:R400C1=RC[-3])*('Service Duration by unit'!R1C3:R400C3=_xlfn.MINIFS('Service Duration by unit'!R1C3:R400C3,'Service Duration by unit'!R1C1:R400C1,RC[-3],'Service Duration by unit'!R1C3:R400C3,">="&IF(RC[-5]=R4C13,RC[-1],R3C13)))),1))*RC[-2]/3600)*(1+RC[-1])} -> 0 | Q13: {=(IF(RC[-5]=R4C13,RC[-1]*RC[-4],R3C13*RC[-4])+(INDEX(_xlfn._xlws.FILTER('Service Duration by unit'!R1C4:R400C4,('Service Duration by unit'!R1C1:R400C1=RC[-3])*('Service Duration by unit'!R1C3:R400C3=_xlfn.MINIFS('Service Duration by unit'!R1C3:R400C3,'Service Duration by unit'!R1C1:R400C1,RC[-3],'Service Duration by unit'!R1C3:R400C3,">="&IF(RC[-5]=R4C13,RC[-1],R3C13)))),1))*RC[-2]/3600)*(1+RC[-1])} -> 0 | R13: {=(IF(RC[-5]=R4C13,RC[-1]*RC[-4],R3C13*RC[-4])+(INDEX(_xlfn._xlws.FILTER('Service Duration by unit'!R1C4:R400C4,('Service Duration by unit'!R1C1:R400C1=RC[-3])*('Service Duration by unit'!R1C3:R400C3=_xlfn.MINIFS('Service Duration by unit'!R1C3:R400C3,'Service Duration by unit'!R1C1:R400C1,RC[-3],'Service Duration by unit'!R1C3:R400C3,">="&IF(RC[-5]=R4C13,RC[-1],R3C13)))),1))*RC[-2]/3600)*(1+RC[-1])} -> 0 | S13: {=(IF(RC[-5]=R4C13,RC[-1]*RC[-4],R3C13*RC[-4])+(INDEX(_xlfn._xlws.FILTER('Service Duration by unit'!R1C4:R400C4,('Service Duration by unit'!R1C1:R400C1=RC[-3])*('Service Duration by unit'!R1C3:R400C3=_xlfn.MINIFS('Service Duration by unit'!R1C3:R400C3,'Service Duration by unit'!R1C1:R400C1,RC[-3],'Service Duration by unit'!R1C3:R400C3,">="&IF(RC[-5]=R4C13,RC[-1],R3C13)))),1))*RC[-2]/3600)*(1+RC[-1])} -> 0 | T13: {=(IF(RC[-5]=R4C13,RC[-1]*RC[-4],R3C13*RC[-4])+(INDEX(_xlfn._xlws.FILTER('Service Duration by unit'!R1C4:R400C4,('Service Duration by unit'!R1C1:R400C1=RC[-3])*('Service Duration by unit'!R1C3:R400C3=_xlfn.MINIFS('Service Duration by unit'!R1C3:R400C3,'Service Duration by unit'!R1C1:R400C1,RC[-3],'Service Duration by unit'!R1C3:R400C3,">="&IF(RC[-5]=R4C13,RC[-1],R3C13)))),1))*RC[-2]/3600)*(1+RC[-1])} -> 0 | U13: {=(IF(RC[-5]=R4C13,RC[-1]*RC[-4],R3C13*RC[-4])+(INDEX(_xlfn._xlws.FILTER('Service Duration by unit'!R1C4:R400C4,('Service Duration by unit'!R1C1:R400C1=RC[-3])*('Service Duration by unit'!R1C3:R400C3=_xlfn.MINIFS('Service Duration by unit'!R1C3:R400C3,'Service Duration by unit'!R1C1:R400C1,RC[-3],'Service Duration by unit'!R1C3:R400C3,">="&IF(RC[-5]=R4C13,RC[-1],R3C13)))),1))*RC[-2]/3600)*(1+RC[-1])} -> 0 | ... FF13: {=(IF(RC[-5]=R4C13,RC[-1]*RC[-4],R3C13*RC[-4])+(INDEX(_xlfn._xlws.FILTER('Service Duration by unit'!R1C4:R400C4,('Service Duration by unit'!R1C1:R400C1=RC[-3])*('Service Duration by unit'!R1C3:R400C3=_xlfn.MINIFS('Service Duration by unit'!R1C3:R400C3,'Service Duration by unit'!R1C1:R400C1,RC[-3],'Service Duration by unit'!R1C3:R400C3,">="&IF(RC[-5]=R4C13,RC[-1],R3C13)))),1))*RC[-2]/3600)*(1+RC[-1])} -> 0
N14: {=(IF(RC[-5]=R4C13,RC[-1]*RC[-4],R3C13*RC[-4])+(INDEX(_xlfn._xlws.FILTER('Service Duration by unit'!R1C4:R400C4,('Service Duration by unit'!R1C1:R400C1=RC[-3])*('Service Duration by unit'!R1C3:R400C3=_xlfn.MINIFS('Service Duration by unit'!R1C3:R400C3,'Service Duration by unit'!R1C1:R400C1,RC[-3],'Service Duration by unit'!R1C3:R400C3,">="&IF(RC[-5]=R4C13,RC[-1],R3C13)))),1))*RC[-2]/3600)*(1+RC[-1])} -> 0 | O14: {=(IF(RC[-5]=R4C13,RC[-1]*RC[-4],R3C13*RC[-4])+(INDEX(_xlfn._xlws.FILTER('Service Duration by unit'!R1C4:R400C4,('Service Duration by unit'!R1C1:R400C1=RC[-3])*('Service Duration by unit'!R1C3:R400C3=_xlfn.MINIFS('Service Duration by unit'!R1C3:R400C3,'Service Duration by unit'!R1C1:R400C1,RC[-3],'Service Duration by unit'!R1C3:R400C3,">="&IF(RC[-5]=R4C13,RC[-1],R3C13)))),1))*RC[-2]/3600)*(1+RC[-1])} -> 0 | P14: {=(IF(RC[-5]=R4C13,RC[-1]*RC[-4],R3C13*RC[-4])+(INDEX(_xlfn._xlws.FILTER('Service Duration by unit'!R1C4:R400C4,('Service Duration by unit'!R1C1:R400C1=RC[-3])*('Service Duration by unit'!R1C3:R400C3=_xlfn.MINIFS('Service Duration by unit'!R1C3:R400C3,'Service Duration by unit'!R1C1:R400C1,RC[-3],'Service Duration by unit'!R1C3:R400C3,">="&IF(RC[-5]=R4C13,RC[-1],R3C13)))),1))*RC[-2]/3600)*(1+RC[-1])} -> 0 | Q14: {=(IF(RC[-5]=R4C13,RC[-1]*RC[-4],R3C13*RC[-4])+(INDEX(_xlfn._xlws.FILTER('Service Duration by unit'!R1C4:R400C4,('Service Duration by unit'!R1C1:R400C1=RC[-3])*('Service Duration by unit'!R1C3:R400C3=_xlfn.MINIFS('Service Duration by unit'!R1C3:R400C3,'Service Duration by unit'!R1C1:R400C1,RC[-3],'Service Duration by unit'!R1C3:R400C3,">="&IF(RC[-5]=R4C13,RC[-1],R3C13)))),1))*RC[-2]/3600)*(1+RC[-1])} -> 0 | R14: {=(IF(RC[-5]=R4C13,RC[-1]*RC[-4],R3C13*RC[-4])+(INDEX(_xlfn._xlws.FILTER('Service Duration by unit'!R1C4:R400C4,('Service Duration by unit'!R1C1:R400C1=RC[-3])*('Service Duration by unit'!R1C3:R400C3=_xlfn.MINIFS('Service Duration by unit'!R1C3:R400C3,'Service Duration by unit'!R1C1:R400C1,RC[-3],'Service Duration by unit'!R1C3:R400C3,">="&IF(RC[-5]=R4C13,RC[-1],R3C13)))),1))*RC[-2]/3600)*(1+RC[-1])} -> 0 | S14: {=(IF(RC[-5]=R4C13,RC[-1]*RC[-4],R3C13*RC[-4])+(INDEX(_xlfn._xlws.FILTER('Service Duration by unit'!R1C4:R400C4,('Service Duration by unit'!R1C1:R400C1=RC[-3])*('Service Duration by unit'!R1C3:R400C3=_xlfn.MINIFS('Service Duration by unit'!R1C3:R400C3,'Service Duration by unit'!R1C1:R400C1,RC[-3],'Service Duration by unit'!R1C3:R400C3,">="&IF(RC[-5]=R4C13,RC[-1],R3C13)))),1))*RC[-2]/3600)*(1+RC[-1])} -> 0 | T14: {=(IF(RC[-5]=R4C13,RC[-1]*RC[-4],R3C13*RC[-4])+(INDEX(_xlfn._xlws.FILTER('Service Duration by unit'!R1C4:R400C4,('Service Duration by unit'!R1C1:R400C1=RC[-3])*('Service Duration by unit'!R1C3:R400C3=_xlfn.MINIFS('Service Duration by unit'!R1C3:R400C3,'Service Duration by unit'!R1C1:R400C1,RC[-3],'Service Duration by unit'!R1C3:R400C3,">="&IF(RC[-5]=R4C13,RC[-1],R3C13)))),1))*RC[-2]/3600)*(1+RC[-1])} -> 0 | U14: {=(IF(RC[-5]=R4C13,RC[-1]*RC[-4],R3C13*RC[-4])+(INDEX(_xlfn._xlws.FILTER('Service Duration by unit'!R1C4:R400C4,('Service Duration by unit'!R1C1:R400C1=RC[-3])*('Service Duration by unit'!R1C3:R400C3=_xlfn.MINIFS('Service Duration by unit'!R1C3:R400C3,'Service Duration by unit'!R1C1:R400C1,RC[-3],'Service Duration by unit'!R1C3:R400C3,">="&IF(RC[-5]=R4C13,RC[-1],R3C13)))),1))*RC[-2]/3600)*(1+RC[-1])} -> 0 | ... FF14: {=(IF(RC[-5]=R4C13,RC[-1]*RC[-4],R3C13*RC[-4])+(INDEX(_xlfn._xlws.FILTER('Service Duration by unit'!R1C4:R400C4,('Service Duration by unit'!R1C1:R400C1=RC[-3])*('Service Duration by unit'!R1C3:R400C3=_xlfn.MINIFS('Service Duration by unit'!R1C3:R400C3,'Service Duration by unit'!R1C1:R400C1,RC[-3],'Service Duration by unit'!R1C3:R400C3,">="&IF(RC[-5]=R4C13,RC[-1],R3C13)))),1))*RC[-2]/3600)*(1+RC[-1])} -> 0
N15: {=(IF(RC[-5]=R4C13,RC[-1]*RC[-4],R3C13*RC[-4])+(INDEX(_xlfn._xlws.FILTER('Service Duration by unit'!R1C4:R400C4,('Service Duration by unit'!R1C1:R400C1=RC[-3])*('Service Duration by unit'!R1C3:R400C3=_xlfn.MINIFS('Service Duration by unit'!R1C3:R400C3,'Service Duration by unit'!R1C1:R400C1,RC[-3],'Service Duration by unit'!R1C3:R400C3,">="&IF(RC[-5]=R4C13,RC[-1],R3C13)))),1))*RC[-2]/3600)*(1+RC[-1])} -> 0 | O15: {=(IF(RC[-5]=R4C13,RC[-1]*RC[-4],R3C13*RC[-4])+(INDEX(_xlfn._xlws.FILTER('Service Duration by unit'!R1C4:R400C4,('Service Duration by unit'!R1C1:R400C1=RC[-3])*('Service Duration by unit'!R1C3:R400C3=_xlfn.MINIFS('Service Duration by unit'!R1C3:R400C3,'Service Duration by unit'!R1C1:R400C1,RC[-3],'Service Duration by unit'!R1C3:R400C3,">="&IF(RC[-5]=R4C13,RC[-1],R3C13)))),1))*RC[-2]/3600)*(1+RC[-1])} -> 0 | P15: {=(IF(RC[-5]=R4C13,RC[-1]*RC[-4],R3C13*RC[-4])+(INDEX(_xlfn._xlws.FILTER('Service Duration by unit'!R1C4:R400C4,('Service Duration by unit'!R1C1:R400C1=RC[-3])*('Service Duration by unit'!R1C3:R400C3=_xlfn.MINIFS('Service Duration by unit'!R1C3:R400C3,'Service Duration by unit'!R1C1:R400C1,RC[-3],'Service Duration by unit'!R1C3:R400C3,">="&IF(RC[-5]=R4C13,RC[-1],R3C13)))),1))*RC[-2]/3600)*(1+RC[-1])} -> 0 | Q15: {=(IF(RC[-5]=R4C13,RC[-1]*RC[-4],R3C13*RC[-4])+(INDEX(_xlfn._xlws.FILTER('Service Duration by unit'!R1C4:R400C4,('Service Duration by unit'!R1C1:R400C1=RC[-3])*('Service Duration by unit'!R1C3:R400C3=_xlfn.MINIFS('Service Duration by unit'!R1C3:R400C3,'Service Duration by unit'!R1C1:R400C1,RC[-3],'Service Duration by unit'!R1C3:R400C3,">="&IF(RC[-5]=R4C13,RC[-1],R3C13)))),1))*RC[-2]/3600)*(1+RC[-1])} -> 0 | R15: {=(IF(RC[-5]=R4C13,RC[-1]*RC[-4],R3C13*RC[-4])+(INDEX(_xlfn._xlws.FILTER('Service Duration by unit'!R1C4:R400C4,('Service Duration by unit'!R1C1:R400C1=RC[-3])*('Service Duration by unit'!R1C3:R400C3=_xlfn.MINIFS('Service Duration by unit'!R1C3:R400C3,'Service Duration by unit'!R1C1:R400C1,RC[-3],'Service Duration by unit'!R1C3:R400C3,">="&IF(RC[-5]=R4C13,RC[-1],R3C13)))),1))*RC[-2]/3600)*(1+RC[-1])} -> 0 | S15: {=(IF(RC[-5]=R4C13,RC[-1]*RC[-4],R3C13*RC[-4])+(INDEX(_xlfn._xlws.FILTER('Service Duration by unit'!R1C4:R400C4,('Service Duration by unit'!R1C1:R400C1=RC[-3])*('Service Duration by unit'!R1C3:R400C3=_xlfn.MINIFS('Service Duration by unit'!R1C3:R400C3,'Service Duration by unit'!R1C1:R400C1,RC[-3],'Service Duration by unit'!R1C3:R400C3,">="&IF(RC[-5]=R4C13,RC[-1],R3C13)))),1))*RC[-2]/3600)*(1+RC[-1])} -> 0 | T15: {=(IF(RC[-5]=R4C13,RC[-1]*RC[-4],R3C13*RC[-4])+(INDEX(_xlfn._xlws.FILTER('Service Duration by unit'!R1C4:R400C4,('Service Duration by unit'!R1C1:R400C1=RC[-3])*('Service Duration by unit'!R1C3:R400C3=_xlfn.MINIFS('Service Duration by unit'!R1C3:R400C3,'Service Duration by unit'!R1C1:R400C1,RC[-3],'Service Duration by unit'!R1C3:R400C3,">="&IF(RC[-5]=R4C13,RC[-1],R3C13)))),1))*RC[-2]/3600)*(1+RC[-1])} -> 0 | U15: {=(IF(RC[-5]=R4C13,RC[-1]*RC[-4],R3C13*RC[-4])+(INDEX(_xlfn._xlws.FILTER('Service Duration by unit'!R1C4:R400C4,('Service Duration by unit'!R1C1:R400C1=RC[-3])*('Service Duration by unit'!R1C3:R400C3=_xlfn.MINIFS('Service Duration by unit'!R1C3:R400C3,'Service Duration by unit'!R1C1:R400C1,RC[-3],'Service Duration by unit'!R1C3:R400C3,">="&IF(RC[-5]=R4C13,RC[-1],R3C13)))),1))*RC[-2]/3600)*(1+RC[-1])} -> 0 | ... FF15: {=(IF(RC[-5]=R4C13,RC[-1]*RC[-4],R3C13*RC[-4])+(INDEX(_xlfn._xlws.FILTER('Service Duration by unit'!R1C4:R400C4,('Service Duration by unit'!R1C1:R400C1=RC[-3])*('Service Duration by unit'!R1C3:R400C3=_xlfn.MINIFS('Service Duration by unit'!R1C3:R400C3,'Service Duration by unit'!R1C1:R400C1,RC[-3],'Service Duration by unit'!R1C3:R400C3,">="&IF(RC[-5]=R4C13,RC[-1],R3C13)))),1))*RC[-2]/3600)*(1+RC[-1])} -> 0
N16: {=(IF(RC[-5]=R4C13,RC[-1]*RC[-4],R3C13*RC[-4])+(INDEX(_xlfn._xlws.FILTER('Service Duration by unit'!R1C4:R400C4,('Service Duration by unit'!R1C1:R400C1=RC[-3])*('Service Duration by unit'!R1C3:R400C3=_xlfn.MINIFS('Service Duration by unit'!R1C3:R400C3,'Service Duration by unit'!R1C1:R400C1,RC[-3],'Service Duration by unit'!R1C3:R400C3,">="&IF(RC[-5]=R4C13,RC[-1],R3C13)))),1))*RC[-2]/3600)*(1+RC[-1])} -> 0 | O16: {=(IF(RC[-5]=R4C13,RC[-1]*RC[-4],R3C13*RC[-4])+(INDEX(_xlfn._xlws.FILTER('Service Duration by unit'!R1C4:R400C4,('Service Duration by unit'!R1C1:R400C1=RC[-3])*('Service Duration by unit'!R1C3:R400C3=_xlfn.MINIFS('Service Duration by unit'!R1C3:R400C3,'Service Duration by unit'!R1C1:R400C1,RC[-3],'Service Duration by unit'!R1C3:R400C3,">="&IF(RC[-5]=R4C13,RC[-1],R3C13)))),1))*RC[-2]/3600)*(1+RC[-1])} -> 0 | P16: {=(IF(RC[-5]=R4C13,RC[-1]*RC[-4],R3C13*RC[-4])+(INDEX(_xlfn._xlws.FILTER('Service Duration by unit'!R1C4:R400C4,('Service Duration by unit'!R1C1:R400C1=RC[-3])*('Service Duration by unit'!R1C3:R400C3=_xlfn.MINIFS('Service Duration by unit'!R1C3:R400C3,'Service Duration by unit'!R1C1:R400C1,RC[-3],'Service Duration by unit'!R1C3:R400C3,">="&IF(RC[-5]=R4C13,RC[-1],R3C13)))),1))*RC[-2]/3600)*(1+RC[-1])} -> 0 | Q16: {=(IF(RC[-5]=R4C13,RC[-1]*RC[-4],R3C13*RC[-4])+(INDEX(_xlfn._xlws.FILTER('Service Duration by unit'!R1C4:R400C4,('Service Duration by unit'!R1C1:R400C1=RC[-3])*('Service Duration by unit'!R1C3:R400C3=_xlfn.MINIFS('Service Duration by unit'!R1C3:R400C3,'Service Duration by unit'!R1C1:R400C1,RC[-3],'Service Duration by unit'!R1C3:R400C3,">="&IF(RC[-5]=R4C13,RC[-1],R3C13)))),1))*RC[-2]/3600)*(1+RC[-1])} -> 0 | R16: {=(IF(RC[-5]=R4C13,RC[-1]*RC[-4],R3C13*RC[-4])+(INDEX(_xlfn._xlws.FILTER('Service Duration by unit'!R1C4:R400C4,('Service Duration by unit'!R1C1:R400C1=RC[-3])*('Service Duration by unit'!R1C3:R400C3=_xlfn.MINIFS('Service Duration by unit'!R1C3:R400C3,'Service Duration by unit'!R1C1:R400C1,RC[-3],'Service Duration by unit'!R1C3:R400C3,">="&IF(RC[-5]=R4C13,RC[-1],R3C13)))),1))*RC[-2]/3600)*(1+RC[-1])} -> 0 | S16: {=(IF(RC[-5]=R4C13,RC[-1]*RC[-4],R3C13*RC[-4])+(INDEX(_xlfn._xlws.FILTER('Service Duration by unit'!R1C4:R400C4,('Service Duration by unit'!R1C1:R400C1=RC[-3])*('Service Duration by unit'!R1C3:R400C3=_xlfn.MINIFS('Service Duration by unit'!R1C3:R400C3,'Service Duration by unit'!R1C1:R400C1,RC[-3],'Service Duration by unit'!R1C3:R400C3,">="&IF(RC[-5]=R4C13,RC[-1],R3C13)))),1))*RC[-2]/3600)*(1+RC[-1])} -> 0 | T16: {=(IF(RC[-5]=R4C13,RC[-1]*RC[-4],R3C13*RC[-4])+(INDEX(_xlfn._xlws.FILTER('Service Duration by unit'!R1C4:R400C4,('Service Duration by unit'!R1C1:R400C1=RC[-3])*('Service Duration by unit'!R1C3:R400C3=_xlfn.MINIFS('Service Duration by unit'!R1C3:R400C3,'Service Duration by unit'!R1C1:R400C1,RC[-3],'Service Duration by unit'!R1C3:R400C3,">="&IF(RC[-5]=R4C13,RC[-1],R3C13)))),1))*RC[-2]/3600)*(1+RC[-1])} -> 0 | U16: {=(IF(RC[-5]=R4C13,RC[-1]*RC[-4],R3C13*RC[-4])+(INDEX(_xlfn._xlws.FILTER('Service Duration by unit'!R1C4:R400C4,('Service Duration by unit'!R1C1:R400C1=RC[-3])*('Service Duration by unit'!R1C3:R400C3=_xlfn.MINIFS('Service Duration by unit'!R1C3:R400C3,'Service Duration by unit'!R1C1:R400C1,RC[-3],'Service Duration by unit'!R1C3:R400C3,">="&IF(RC[-5]=R4C13,RC[-1],R3C13)))),1))*RC[-2]/3600)*(1+RC[-1])} -> 0 | ... FF16: {=(IF(RC[-5]=R4C13,RC[-1]*RC[-4],R3C13*RC[-4])+(INDEX(_xlfn._xlws.FILTER('Service Duration by unit'!R1C4:R400C4,('Service Duration by unit'!R1C1:R400C1=RC[-3])*('Service Duration by unit'!R1C3:R400C3=_xlfn.MINIFS('Service Duration by unit'!R1C3:R400C3,'Service Duration by unit'!R1C1:R400C1,RC[-3],'Service Duration by unit'!R1C3:R400C3,">="&IF(RC[-5]=R4C13,RC[-1],R3C13)))),1))*RC[-2]/3600)*(1+RC[-1])} -> 0
N17: {=(IF(RC[-5]=R4C13,RC[-1]*RC[-4],R3C13*RC[-4])+(INDEX(_xlfn._xlws.FILTER('Service Duration by unit'!R1C4:R400C4,('Service Duration by unit'!R1C1:R400C1=RC[-3])*('Service Duration by unit'!R1C3:R400C3=_xlfn.MINIFS('Service Duration by unit'!R1C3:R400C3,'Service Duration by unit'!R1C1:R400C1,RC[-3],'Service Duration by unit'!R1C3:R400C3,">="&IF(RC[-5]=R4C13,RC[-1],R3C13)))),1))*RC[-2]/3600)*(1+RC[-1])} -> 0 | O17: {=(IF(RC[-5]=R4C13,RC[-1]*RC[-4],R3C13*RC[-4])+(INDEX(_xlfn._xlws.FILTER('Service Duration by unit'!R1C4:R400C4,('Service Duration by unit'!R1C1:R400C1=RC[-3])*('Service Duration by unit'!R1C3:R400C3=_xlfn.MINIFS('Service Duration by unit'!R1C3:R400C3,'Service Duration by unit'!R1C1:R400C1,RC[-3],'Service Duration by unit'!R1C3:R400C3,">="&IF(RC[-5]=R4C13,RC[-1],R3C13)))),1))*RC[-2]/3600)*(1+RC[-1])} -> 0 | P17: {=(IF(RC[-5]=R4C13,RC[-1]*RC[-4],R3C13*RC[-4])+(INDEX(_xlfn._xlws.FILTER('Service Duration by unit'!R1C4:R400C4,('Service Duration by unit'!R1C1:R400C1=RC[-3])*('Service Duration by unit'!R1C3:R400C3=_xlfn.MINIFS('Service Duration by unit'!R1C3:R400C3,'Service Duration by unit'!R1C1:R400C1,RC[-3],'Service Duration by unit'!R1C3:R400C3,">="&IF(RC[-5]=R4C13,RC[-1],R3C13)))),1))*RC[-2]/3600)*(1+RC[-1])} -> 0 | Q17: {=(IF(RC[-5]=R4C13,RC[-1]*RC[-4],R3C13*RC[-4])+(INDEX(_xlfn._xlws.FILTER('Service Duration by unit'!R1C4:R400C4,('Service Duration by unit'!R1C1:R400C1=RC[-3])*('Service Duration by unit'!R1C3:R400C3=_xlfn.MINIFS('Service Duration by unit'!R1C3:R400C3,'Service Duration by unit'!R1C1:R400C1,RC[-3],'Service Duration by unit'!R1C3:R400C3,">="&IF(RC[-5]=R4C13,RC[-1],R3C13)))),1))*RC[-2]/3600)*(1+RC[-1])} -> 0 | R17: {=(IF(RC[-5]=R4C13,RC[-1]*RC[-4],R3C13*RC[-4])+(INDEX(_xlfn._xlws.FILTER('Service Duration by unit'!R1C4:R400C4,('Service Duration by unit'!R1C1:R400C1=RC[-3])*('Service Duration by unit'!R1C3:R400C3=_xlfn.MINIFS('Service Duration by unit'!R1C3:R400C3,'Service Duration by unit'!R1C1:R400C1,RC[-3],'Service Duration by unit'!R1C3:R400C3,">="&IF(RC[-5]=R4C13,RC[-1],R3C13)))),1))*RC[-2]/3600)*(1+RC[-1])} -> 0 | S17: {=(IF(RC[-5]=R4C13,RC[-1]*RC[-4],R3C13*RC[-4])+(INDEX(_xlfn._xlws.FILTER('Service Duration by unit'!R1C4:R400C4,('Service Duration by unit'!R1C1:R400C1=RC[-3])*('Service Duration by unit'!R1C3:R400C3=_xlfn.MINIFS('Service Duration by unit'!R1C3:R400C3,'Service Duration by unit'!R1C1:R400C1,RC[-3],'Service Duration by unit'!R1C3:R400C3,">="&IF(RC[-5]=R4C13,RC[-1],R3C13)))),1))*RC[-2]/3600)*(1+RC[-1])} -> 0 | T17: {=(IF(RC[-5]=R4C13,RC[-1]*RC[-4],R3C13*RC[-4])+(INDEX(_xlfn._xlws.FILTER('Service Duration by unit'!R1C4:R400C4,('Service Duration by unit'!R1C1:R400C1=RC[-3])*('Service Duration by unit'!R1C3:R400C3=_xlfn.MINIFS('Service Duration by unit'!R1C3:R400C3,'Service Duration by unit'!R1C1:R400C1,RC[-3],'Service Duration by unit'!R1C3:R400C3,">="&IF(RC[-5]=R4C13,RC[-1],R3C13)))),1))*RC[-2]/3600)*(1+RC[-1])} -> 0 | U17: {=(IF(RC[-5]=R4C13,RC[-1]*RC[-4],R3C13*RC[-4])+(INDEX(_xlfn._xlws.FILTER('Service Duration by unit'!R1C4:R400C4,('Service Duration by unit'!R1C1:R400C1=RC[-3])*('Service Duration by unit'!R1C3:R400C3=_xlfn.MINIFS('Service Duration by unit'!R1C3:R400C3,'Service Duration by unit'!R1C1:R400C1,RC[-3],'Service Duration by unit'!R1C3:R400C3,">="&IF(RC[-5]=R4C13,RC[-1],R3C13)))),1))*RC[-2]/3600)*(1+RC[-1])} -> 0 | ... FF17: {=(IF(RC[-5]=R4C13,RC[-1]*RC[-4],R3C13*RC[-4])+(INDEX(_xlfn._xlws.FILTER('Service Duration by unit'!R1C4:R400C4,('Service Duration by unit'!R1C1:R400C1=RC[-3])*('Service Duration by unit'!R1C3:R400C3=_xlfn.MINIFS('Service Duration by unit'!R1C3:R400C3,'Service Duration by unit'!R1C1:R400C1,RC[-3],'Service Duration by unit'!R1C3:R400C3,">="&IF(RC[-5]=R4C13,RC[-1],R3C13)))),1))*RC[-2]/3600)*(1+RC[-1])} -> 0
N18: {=(IF(RC[-5]=R4C13,RC[-1]*RC[-4],R3C13*RC[-4])+(INDEX(_xlfn._xlws.FILTER('Service Duration by unit'!R1C4:R400C4,('Service Duration by unit'!R1C1:R400C1=RC[-3])*('Service Duration by unit'!R1C3:R400C3=_xlfn.MINIFS('Service Duration by unit'!R1C3:R400C3,'Service Duration by unit'!R1C1:R400C1,RC[-3],'Service Duration by unit'!R1C3:R400C3,">="&IF(RC[-5]=R4C13,RC[-1],R3C13)))),1))*RC[-2]/3600)*(1+RC[-1])} -> 0 | O18: {=(IF(RC[-5]=R4C13,RC[-1]*RC[-4],R3C13*RC[-4])+(INDEX(_xlfn._xlws.FILTER('Service Duration by unit'!R1C4:R400C4,('Service Duration by unit'!R1C1:R400C1=RC[-3])*('Service Duration by unit'!R1C3:R400C3=_xlfn.MINIFS('Service Duration by unit'!R1C3:R400C3,'Service Duration by unit'!R1C1:R400C1,RC[-3],'Service Duration by unit'!R1C3:R400C3,">="&IF(RC[-5]=R4C13,RC[-1],R3C13)))),1))*RC[-2]/3600)*(1+RC[-1])} -> 0 | P18: {=(IF(RC[-5]=R4C13,RC[-1]*RC[-4],R3C13*RC[-4])+(INDEX(_xlfn._xlws.FILTER('Service Duration by unit'!R1C4:R400C4,('Service Duration by unit'!R1C1:R400C1=RC[-3])*('Service Duration by unit'!R1C3:R400C3=_xlfn.MINIFS('Service Duration by unit'!R1C3:R400C3,'Service Duration by unit'!R1C1:R400C1,RC[-3],'Service Duration by unit'!R1C3:R400C3,">="&IF(RC[-5]=R4C13,RC[-1],R3C13)))),1))*RC[-2]/3600)*(1+RC[-1])} -> 0 | Q18: {=(IF(RC[-5]=R4C13,RC[-1]*RC[-4],R3C13*RC[-4])+(INDEX(_xlfn._xlws.FILTER('Service Duration by unit'!R1C4:R400C4,('Service Duration by unit'!R1C1:R400C1=RC[-3])*('Service Duration by unit'!R1C3:R400C3=_xlfn.MINIFS('Service Duration by unit'!R1C3:R400C3,'Service Duration by unit'!R1C1:R400C1,RC[-3],'Service Duration by unit'!R1C3:R400C3,">="&IF(RC[-5]=R4C13,RC[-1],R3C13)))),1))*RC[-2]/3600)*(1+RC[-1])} -> 0 | R18: {=(IF(RC[-5]=R4C13,RC[-1]*RC[-4],R3C13*RC[-4])+(INDEX(_xlfn._xlws.FILTER('Service Duration by unit'!R1C4:R400C4,('Service Duration by unit'!R1C1:R400C1=RC[-3])*('Service Duration by unit'!R1C3:R400C3=_xlfn.MINIFS('Service Duration by unit'!R1C3:R400C3,'Service Duration by unit'!R1C1:R400C1,RC[-3],'Service Duration by unit'!R1C3:R400C3,">="&IF(RC[-5]=R4C13,RC[-1],R3C13)))),1))*RC[-2]/3600)*(1+RC[-1])} -> 0 | S18: {=(IF(RC[-5]=R4C13,RC[-1]*RC[-4],R3C13*RC[-4])+(INDEX(_xlfn._xlws.FILTER('Service Duration by unit'!R1C4:R400C4,('Service Duration by unit'!R1C1:R400C1=RC[-3])*('Service Duration by unit'!R1C3:R400C3=_xlfn.MINIFS('Service Duration by unit'!R1C3:R400C3,'Service Duration by unit'!R1C1:R400C1,RC[-3],'Service Duration by unit'!R1C3:R400C3,">="&IF(RC[-5]=R4C13,RC[-1],R3C13)))),1))*RC[-2]/3600)*(1+RC[-1])} -> 0 | T18: {=(IF(RC[-5]=R4C13,RC[-1]*RC[-4],R3C13*RC[-4])+(INDEX(_xlfn._xlws.FILTER('Service Duration by unit'!R1C4:R400C4,('Service Duration by unit'!R1C1:R400C1=RC[-3])*('Service Duration by unit'!R1C3:R400C3=_xlfn.MINIFS('Service Duration by unit'!R1C3:R400C3,'Service Duration by unit'!R1C1:R400C1,RC[-3],'Service Duration by unit'!R1C3:R400C3,">="&IF(RC[-5]=R4C13,RC[-1],R3C13)))),1))*RC[-2]/3600)*(1+RC[-1])} -> 0 | U18: {=(IF(RC[-5]=R4C13,RC[-1]*RC[-4],R3C13*RC[-4])+(INDEX(_xlfn._xlws.FILTER('Service Duration by unit'!R1C4:R400C4,('Service Duration by unit'!R1C1:R400C1=RC[-3])*('Service Duration by unit'!R1C3:R400C3=_xlfn.MINIFS('Service Duration by unit'!R1C3:R400C3,'Service Duration by unit'!R1C1:R400C1,RC[-3],'Service Duration by unit'!R1C3:R400C3,">="&IF(RC[-5]=R4C13,RC[-1],R3C13)))),1))*RC[-2]/3600)*(1+RC[-1])} -> 0 | ... FF18: {=(IF(RC[-5]=R4C13,RC[-1]*RC[-4],R3C13*RC[-4])+(INDEX(_xlfn._xlws.FILTER('Service Duration by unit'!R1C4:R400C4,('Service Duration by unit'!R1C1:R400C1=RC[-3])*('Service Duration by unit'!R1C3:R400C3=_xlfn.MINIFS('Service Duration by unit'!R1C3:R400C3,'Service Duration by unit'!R1C1:R400C1,RC[-3],'Service Duration by unit'!R1C3:R400C3,">="&IF(RC[-5]=R4C13,RC[-1],R3C13)))),1))*RC[-2]/3600)*(1+RC[-1])} -> 0
... N50: {=(IF(RC[-5]=R4C13,RC[-1]*RC[-4],R3C13*RC[-4])+(INDEX(_xlfn._xlws.FILTER('Service Duration by unit'!R1C4:R400C4,('Service Duration by unit'!R1C1:R400C1=RC[-3])*('Service Duration by unit'!R1C3:R400C3=_xlfn.MINIFS('Service Duration by unit'!R1C3:R400C3,'Service Duration by unit'!R1C1:R400C1,RC[-3],'Service Duration by unit'!R1C3:R400C3,">="&IF(RC[-5]=R4C13,RC[-1],R3C13)))),1))*RC[-2]/3600)*(1+RC[-1])} -> 0 | O50: {=(IF(RC[-5]=R4C13,RC[-1]*RC[-4],R3C13*RC[-4])+(INDEX(_xlfn._xlws.FILTER('Service Duration by unit'!R1C4:R400C4,('Service Duration by unit'!R1C1:R400C1=RC[-3])*('Service Duration by unit'!R1C3:R400C3=_xlfn.MINIFS('Service Duration by unit'!R1C3:R400C3,'Service Duration by unit'!R1C1:R400C1,RC[-3],'Service Duration by unit'!R1C3:R400C3,">="&IF(RC[-5]=R4C13,RC[-1],R3C13)))),1))*RC[-2]/3600)*(1+RC[-1])} -> 0 | P50: {=(IF(RC[-5]=R4C13,RC[-1]*RC[-4],R3C13*RC[-4])+(INDEX(_xlfn._xlws.FILTER('Service Duration by unit'!R1C4:R400C4,('Service Duration by unit'!R1C1:R400C1=RC[-3])*('Service Duration by unit'!R1C3:R400C3=_xlfn.MINIFS('Service Duration by unit'!R1C3:R400C3,'Service Duration by unit'!R1C1:R400C1,RC[-3],'Service Duration by unit'!R1C3:R400C3,">="&IF(RC[-5]=R4C13,RC[-1],R3C13)))),1))*RC[-2]/3600)*(1+RC[-1])} -> 0 | Q50: {=(IF(RC[-5]=R4C13,RC[-1]*RC[-4],R3C13*RC[-4])+(INDEX(_xlfn._xlws.FILTER('Service Duration by unit'!R1C4:R400C4,('Service Duration by unit'!R1C1:R400C1=RC[-3])*('Service Duration by unit'!R1C3:R400C3=_xlfn.MINIFS('Service Duration by unit'!R1C3:R400C3,'Service Duration by unit'!R1C1:R400C1,RC[-3],'Service Duration by unit'!R1C3:R400C3,">="&IF(RC[-5]=R4C13,RC[-1],R3C13)))),1))*RC[-2]/3600)*(1+RC[-1])} -> 0 | R50: {=(IF(RC[-5]=R4C13,RC[-1]*RC[-4],R3C13*RC[-4])+(INDEX(_xlfn._xlws.FILTER('Service Duration by unit'!R1C4:R400C4,('Service Duration by unit'!R1C1:R400C1=RC[-3])*('Service Duration by unit'!R1C3:R400C3=_xlfn.MINIFS('Service Duration by unit'!R1C3:R400C3,'Service Duration by unit'!R1C1:R400C1,RC[-3],'Service Duration by unit'!R1C3:R400C3,">="&IF(RC[-5]=R4C13,RC[-1],R3C13)))),1))*RC[-2]/3600)*(1+RC[-1])} -> 0 | S50: {=(IF(RC[-5]=R4C13,RC[-1]*RC[-4],R3C13*RC[-4])+(INDEX(_xlfn._xlws.FILTER('Service Duration by unit'!R1C4:R400C4,('Service Duration by unit'!R1C1:R400C1=RC[-3])*('Service Duration by unit'!R1C3:R400C3=_xlfn.MINIFS('Service Duration by unit'!R1C3:R400C3,'Service Duration by unit'!R1C1:R400C1,RC[-3],'Service Duration by unit'!R1C3:R400C3,">="&IF(RC[-5]=R4C13,RC[-1],R3C13)))),1))*RC[-2]/3600)*(1+RC[-1])} -> 0 | T50: {=(IF(RC[-5]=R4C13,RC[-1]*RC[-4],R3C13*RC[-4])+(INDEX(_xlfn._xlws.FILTER('Service Duration by unit'!R1C4:R400C4,('Service Duration by unit'!R1C1:R400C1=RC[-3])*('Service Duration by unit'!R1C3:R400C3=_xlfn.MINIFS('Service Duration by unit'!R1C3:R400C3,'Service Duration by unit'!R1C1:R400C1,RC[-3],'Service Duration by unit'!R1C3:R400C3,">="&IF(RC[-5]=R4C13,RC[-1],R3C13)))),1))*RC[-2]/3600)*(1+RC[-1])} -> 0 | U50: {=(IF(RC[-5]=R4C13,RC[-1]*RC[-4],R3C13*RC[-4])+(INDEX(_xlfn._xlws.FILTER('Service Duration by unit'!R1C4:R400C4,('Service Duration by unit'!R1C1:R400C1=RC[-3])*('Service Duration by unit'!R1C3:R400C3=_xlfn.MINIFS('Service Duration by unit'!R1C3:R400C3,'Service Duration by unit'!R1C1:R400C1,RC[-3],'Service Duration by unit'!R1C3:R400C3,">="&IF(RC[-5]=R4C13,RC[-1],R3C13)))),1))*RC[-2]/3600)*(1+RC[-1])} -> 0 | ... FF50: {=(IF(RC[-5]=R4C13,RC[-1]*RC[-4],R3C13*RC[-4])+(INDEX(_xlfn._xlws.FILTER('Service Duration by unit'!R1C4:R400C4,('Service Duration by unit'!R1C1:R400C1=RC[-3])*('Service Duration by unit'!R1C3:R400C3=_xlfn.MINIFS('Service Duration by unit'!R1C3:R400C3,'Service Duration by unit'!R1C1:R400C1,RC[-3],'Service Duration by unit'!R1C3:R400C3,">="&IF(RC[-5]=R4C13,RC[-1],R3C13)))),1))*RC[-2]/3600)*(1+RC[-1])} -> 0

Sheet Service Duration by unit
A1: Associated Service
A2: TEST - Cutting Glass
A3: TEST - Cutting Glass
A4: TEST - Cutting Glass
A5: TEST - Cutting Glass
A6: TEST - Cutting Glass
A7: TEST - Cutting Wood
A8: TEST - Cutting Wood
A9: TEST - Cutting Wood
A10: Lijst snijden
A11: Lijst snijden
A12: Lijst snijden
... A294: Monteren Crate
A295: Monteren Crate | B295: Work Center A | C295: 4 | D295: 5000

Sheet Dimension
A4: (in m²)
A5: (in m) | B5: Circumference
B8: Data provided from craft | C8: 5.0 x 5.0 | D8: 70.0 x 70.0 | E8: 75.0 x 75.0 | F8: 80.0 x 80.0 | G8: 85.0 x 85.0 | H8: 90.0 x 90.0 | I8: 95.0 x 95.0 | J8: 100.0 x 100.0 | K8: 105.0 x 105.0 | L8: 110.0 x 110.0 | M8: 115.0 x 115.0 | N8: {=(IF(RC[-5]=R4C13,RC[-1]*RC[-4],R3C13*RC[-4])+(INDEX(_xlfn._xlws.FILTER('Service Duration by unit'!R1C4:R400C4,('Service Duration by unit'!R1C1:R400C1=RC[-3])*('Service Duration by unit'!R1C3:R400C3=_xlfn.MINIFS('Service Duration by unit'!R1C3:R400C3,'Service Duration by unit'!R1C1:R400C1,RC[-3],'Service Duration by unit'!R1C3:R400C3,">="&IF(RC[-5]=R4C13,RC[-1],R3C13)))),1))*RC[-2]/3600)*(1+RC[-1])} -> 0 | O8: {=(IF(RC[-5]=R4C13,RC[-1]*RC[-4],R3C13*RC[-4])+(INDEX(_xlfn._xlws.FILTER('Service Duration by unit'!R1C4:R400C4,('Service Duration by unit'!R1C1:R400C1=RC[-3])*('Service Duration by unit'!R1C3:R400C3=_xlfn.MINIFS('Service Duration by unit'!R1C3:R400C3,'Service Duration by unit'!R1C1:R400C1,RC[-3],'Service Duration by unit'!R1C3:R400C3,">="&IF(RC[-5]=R4C13,RC[-1],R3C13)))),1))*RC[-2]/3600)*(1+RC[-1])} -> 0 | P8: {=(IF(RC[-5]=R4C13,RC[-1]*RC[-4],R3C13*RC[-4])+(INDEX(_xlfn._xlws.FILTER('Service Duration by unit'!R1C4:R400C4,('Service Duration by unit'!R1C1:R400C1=RC[-3])*('Service Duration by unit'!R1C3:R400C3=_xlfn.MINIFS('Service Duration by unit'!R1C3:R400C3,'Service Duration by unit'!R1C1:R400C1,RC[-3],'Service Duration by unit'!R1C3:R400C3,">="&IF(RC[-5]=R4C13,RC[-1],R3C13)))),1))*RC[-2]/3600)*(1+RC[-1])} -> 0 | Q8: {=(IF(RC[-5]=R4C13,RC[-1]*RC[-4],R3C13*RC[-4])+(INDEX(_xlfn._xlws.FILTER('Service Duration by unit'!R1C4:R400C4,('Service Duration by unit'!R1C1:R400C1=RC[-3])*('Service Duration by unit'!R1C3:R400C3=_xlfn.MINIFS('Service Duration by unit'!R1C3:R400C3,'Service Duration by unit'!R1C1:R400C1,RC[-3],'Service Duration by unit'!R1C3:R400C3,">="&IF(RC[-5]=R4C13,RC[-1],R3C13)))),1))*RC[-2]/3600)*(1+RC[-1])} -> 0 | R8: {=(IF(RC[-5]=R4C13,RC[-1]*RC[-4],R3C13*RC[-4])+(INDEX(_xlfn._xlws.FILTER('Service Duration by unit'!R1C4:R400C4,('Service Duration by unit'!R1C1:R400C1=RC[-3])*('Service Duration by unit'!R1C3:R400C3=_xlfn.MINIFS('Service Duration by unit'!R1C3:R400C3,'Service Duration by unit'!R1C1:R400C1,RC[-3],'Service Duration by unit'!R1C3:R400C3,">="&IF(RC[-5]=R4C13,RC[-1],R3C13)))),1))*RC[-2]/3600)*(1+RC[-1])} -> 0 | S8: {=(IF(RC[-5]=R4C13,RC[-1]*RC[-4],R3C13*RC[-4])+(INDEX(_xlfn._xlws.FILTER('Service Duration by unit'!R1C4:R400C4,('Service Duration by unit'!R1C1:R400C1=RC[-3])*('Service Duration by unit'!R1C3:R400C3=_xlfn.MINIFS('Service Duration by unit'!R1C3:R400C3,'Service Duration by unit'!R1C1:R400C1,RC[-3],'Service Duration by unit'!R1C3:R400C3,">="&IF(RC[-5]=R4C13,RC[-1],R3C13)))),1))*RC[-2]/3600)*(1+RC[-1])} -> 0 | T8: {=(IF(RC[-5]=R4C13,RC[-1]*RC[-4],R3C13*RC[-4])+(INDEX(_xlfn._xlws.FILTER('Service Duration by unit'!R1C4:R400C4,('Service Duration by unit'!R1C1:R400C1=RC[-3])*('Service Duration by unit'!R1C3:R400C3=_xlfn.MINIFS('Service Duration by unit'!R1C3:R400C3,'Service Duration by unit'!R1C1:R400C1,RC[-3],'Service Duration by unit'!R1C3:R400C3,">="&IF(RC[-5]=R4C13,RC[-1],R3C13)))),1))*RC[-2]/3600)*(1+RC[-1])} -> 0 | U8: {=(IF(RC[-5]=R4C13,RC[-1]*RC[-4],R3C13*RC[-4])+(INDEX(_xlfn._xlws.FILTER('Service Duration by unit'!R1C4:R400C4,('Service Duration by unit'!R1C1:R400C1=RC[-3])*('Service Duration by unit'!R1C3:R400C3=_xlfn.MINIFS('Service Duration by unit'!R1C3:R400C3,'Service Duration by unit'!R1C1:R400C1,RC[-3],'Service Duration by unit'!R1C3:R400C3,">="&IF(RC[-5]=R4C13,RC[-1],R3C13)))),1))*RC[-2]/3600)*(1+RC[-1])} -> 0 | ... FF8: {=(IF(RC[-5]=R4C13,RC[-1]*RC[-4],R3C13*RC[-4])+(INDEX(_xlfn._xlws.FILTER('Service Duration by unit'!R1C4:R400C4,('Service Duration by unit'!R1C1:R400C1=RC[-3])*('Service Duration by unit'!R1C3:R400C3=_xlfn.MINIFS('Service Duration by unit'!R1C3:R400C3,'Service Duration by unit'!R1C1:R400C1,RC[-3],'Service Duration by unit'!R1C3:R400C3,">="&IF(RC[-5]=R4C13,RC[-1],R3C13)))),1))*RC[-2]/3600)*(1+RC[-1])} -> 0
